Workbook
Name ADRI: #REF!
Name ALEX_DELCLAUX: #REF!
Name ALVARO_NISTAL: #REF!
Name ANGEL: #REF!
Name ANNA: #REF!
Name ASTARLOA: #REF!
Name BALTHAZAR__VINTED: #REF!
Name BARALLOBRE: #REF!
Name BARTA: #REF!
Name BRUNO: #REF!
Name CAMACHO: #REF!
Name CANALES: #REF!
Name CANDELA: #REF!
Name CARLOTA: #REF!
Name CARMEN: #REF!
Name CASADO: #REF!
Name CASAPE: #REF!
Name CHIARRI: #REF!
Name CHORVO: #REF!
Name CRIS_ARTEAGA: #REF!
Name CUERVO: #REF!
Name DIEGO: #REF!
Name DIEGUITO: #REF!
Name DIRECTOR: #REF!
Name DOMINGUEZ: #REF!
Name FELIX: #REF!
Name FORMARIZ: #REF!
Name GA: #REF!
Name GABRIEL: #REF!
Name GENOVEVA: #REF!
Name IAGO: #REF!
Name IÑIGO: #REF!
Name JAIME_BUSTAMANTE: #REF!
Name JAIME_RAMIREZ: #REF!
Name JAIME_RICO: #REF!
Name JAIME_X: #REF!
Name JORDI: #REF!
Name JOSE: #REF!
Name JP: #REF!
Name JUANMA: #REF!
Name JUANPA: #REF!
Name JUANTO: #REF!
Name JUST.JEANNE__VINTED: #REF!
Name LAURA_PUIG: #REF!
Name LUIS_CANADA: #REF!
Name LYDIABELLET__VINTED: #REF!
Name MARIO_MIRON: #REF!
Name MARQUINA: #REF!
Name MONICA: #REF!
Name MUÑOZ: #REF!
Name NACHO_DE_BENITO: #REF!
Name NACHO_PEREZ: #REF!
Name NATHAN: #REF!
Name NICO_DIAMANTO: #REF!
Name NICO_RUIZ: #REF!
Name PEREZ: #REF!
Name PETER: #REF!
Name PUIG: #REF!
Name PUPI: #REF!
Name QUINTANA: #REF!

Sheet CLIENTES
A1: CLIENTES | E1: CLIENTE | F1: TALLA 2 | G1: TALLA | H1: UNIDADES | I1: INGRESO | J1: DROP
A2: AGO | D2: =1 -> 1 | E2: {='DROP 1'!B65:G65} -> JAIME MILL | F2: M | G2: 1 | H2: 3 | I2: 120 | J2: DROP 1 | L2: Etiquetas de fila | M2: Suma de INGRESO | O2: Etiquetas de fila | P2: Suma de UNIDADES
A3: ALEX DELCAUX | D3: =D2+1 -> 2 | E3: {='DROP 1'!B66:G66} -> PETER | F3: M | G3: 1 | H3: 2 | I3: 105 | J3: DROP 1 | L3: PETER | M3: 421 | O3: L | P3: 100
A4: ALEX GARCIA | D4: =D3+1 -> 3 | E4: {='DROP 1'!B67:G67} -> LUIS CANADA | F4: M | G4: 1 | H4: 2 | I4: 80 | J4: DROP 1 | L4: A33 X NO ART | M4: 70 | O4: M | P4: 85
A5: ALVARO GOMEZ | D5: =D4+1 -> 4 | E5: {='DROP 1'!B68:G68} -> JAIME BUSTAMANTE | F5: M | G5: 1 | H5: 3 | I5: 112 | J5: DROP 1 | L5: DROP 1 | M5: 105 | O5: M, L | P5: 13
A6: ALVARO NISTAL | D6: =D5+1 -> 5 | E6: {='DROP 1'!B69:G69} -> QUINTANA | F6: L | G6: 2 | H6: 1 | I6: 55 | J6: DROP 1 | L6: DROP 2 | M6: 34 | O6: Total general | P6: 198
A7: ALVARO PEREZ | D7: =D6+1 -> 6 | E7: {='DROP 1'!B70:G70} -> MUÑOZ | F7: L | G7: 2 | H7: 4 | I7: 232 | J7: DROP 1 | L7: DROP 3 | M7: 96
A8: AMIGO ANGEL | D8: =D7+1 -> 7 | E8: {='DROP 1'!B71:G71} -> PUIG AMIGO JACO | F8: M | G8: 1 | H8: 1 | I8: 30 | J8: DROP 1 | L8: DROP 4 | M8: 78 | O8: Etiquetas de fila | P8: Suma de UNIDADES
A9: ANA AMIGA JACO | D9: =D8+1 -> 8 | E9: {='DROP 1'!B72:G72} -> GA | F9: M | G9: 1 | H9: 1 | I9: 30 | J9: DROP 1 | L9: DROP 5 | M9: 0 | O9: PETER | P9: 12
A10: ANGEL AMIGO JACO | D10: =D9+1 -> 9 | E10: {='DROP 1'!B73:G73} -> NACHO PEREZ | F10: M | G10: 1 | H10: 1 | I10: 30 | J10: DROP 1 | L10: SUMMER DROP | M10: 38 | O10: JAIME BUSTAMANTE | P10: 12
A11: ASTARLOA | D11: =D10+1 -> 10 | E11: {='DROP 1'!B74:G74} -> CASAPE | F11: M | G11: 1 | H11: 1 | I11: 30 | J11: DROP 1 | L11: MUÑOZ | M11: 398 | O11: MUÑOZ | P11: 11
A12: BARALLOBRE | D12: =D11+1 -> 11 | E12: {='DROP 1'!B75:G75} -> JUANTO | F12: M | G12: 1 | H12: 1 | I12: 55 | J12: DROP 1 | L12: A33 X NO ART | M12: 35 | O12: JUANTO | P12: 8
A13: BARTA | D13: =D12+1 -> 12 | E13: {='DROP 1'!B76:G76} -> DIEGO AMIGO JACO | F13: M | G13: 1 | H13: 1 | I13: 30 | J13: DROP 1 | L13: DROP 1 | M13: 232 | O13: NICO RUIZ | P13: 7
A14: BRUNITO | D14: =D13+1 -> 13 | E14: {='DROP 1'!B77:G77} -> JAIME X | F14: M | G14: 1 | H14: 1 | I14: 30 | J14: DROP 1 | L14: DROP 2 | M14: 78 | O14: BARALLOBRE | P14: 7
A15: CAMACHO | D15: =D14+1 -> 14 | E15: {='DROP 1'!B78:G78} -> AMIGO ANGEL | F15: M | G15: 1 | H15: 1 | I15: 30 | J15: DROP 1 | L15: DROP 4 | M15: 34 | O15: VINTED | P15: 6
A16: CANALES | D16: =D15+1 -> 15 | E16: {='DROP 1'!B79:G79} -> GENOVEVA | F16: M | G16: 1 | H16: 1 | I16: 40 | J16: DROP 1 | L16: DROP 5 | M16: 0 | O16: CHORVO | P16: 6
A17: CANDELA | D17: =D16+1 -> 16 | E17: {='DROP 1'!B80:G80} -> CANDELA | F17: M | G17: 1 | H17: 1 | I17: 40 | J17: DROP 1 | L17: SUMMER DROP | M17: 19 | O17: NACHO PEREZ | P17: 6
A18: CANTERO | D18: =D17+1 -> 17 | E18: {='DROP 2'!B65:G65} -> ANGEL AMIGO JACO | F18: M, L | G18: 3 | H18: 2 | I18: 78 | J18: DROP 2 | L18: JAIME BUSTAMANTE | M18: 393 | O18: DOMINGUEZ | P18: 5
A19: CARLOTA DEL OLMO | D19: =D18+1 -> 18 | E19: {='DROP 2'!B66:G66} -> DIEGO AMIGO JACO | F19: L | G19: 2 | H19: 2 | I19: 63 | J19: DROP 2 | L19: A33 X NO ART | M19: 70 | O19: CASAPE | P19: 5
A20: CARMEN | D20: =D19+1 -> 19 | E20: {='DROP 2'!B67:G67} -> JUANMA | F20: M | G20: 1 | H20: 1 | I20: 29 | J20: DROP 2 | L20: DROP 1 | M20: 112 | O20: QUINTANA | P20: 5
A21: CASADO | D21: =D20+1 -> 20 | E21: {='DROP 2'!B68:G68} -> JUANTO | F21: M | G21: 1 | H21: 2 | I21: 63 | J21: DROP 2 | L21: DROP 2 | M21: 100 | O21: PUIG AMIGO JACO | P21: 5
A22: CASAPE | D22: =D21+1 -> 21 | E22: {='DROP 2'!B69:G69} -> JORGE PUIG | F22: M | G22: 1 | H22: 1 | I22: 49 | J22: DROP 2 | L22: DROP 3 | M22: 33 | O22: JUANMA | P22: 5
A23: CHIARRI | D23: =D22+1 -> 22 | E23: {='DROP 2'!B70:G70} -> NACHO PEREZ | F23: L | G23: 2 | H23: 1 | I23: 34 | J23: DROP 2 | L23: DROP 4 | M23: 78 | O23: BRUNITO | P23: 5
A24: CHORVO | D24: =D23+1 -> 23 | E24: {='DROP 2'!B71:G71} -> PETER | F24: M | G24: 1 | H24: 1 | I24: 34 | J24: DROP 2 | L24: JUANTO | M24: 257 | O24: JORGE PUIG | P24: 5
A25: CRIS ARTEAGA | D25: =D24+1 -> 24 | E25: {='DROP 2'!B72:G72} -> BARALLOBRE | F25: L | G25: 2 | H25: 1 | I25: 29 | J25: DROP 2 | L25: A33 X NO ART | M25: 35 | O25: LUIS CANADA | P25: 4
A26: CUERVO | D26: =D25+1 -> 25 | E26: {='DROP 2'!B73:G73} -> PUIG AMIGO JACO | F26: M | G26: 1 | H26: 2 | I26: 78 | J26: DROP 2 | L26: DROP 1 | M26: 55 | O26: IÑIGO | P26: 4
A27: DIEGO AMIGO JACO | D27: =D26+1 -> 26 | E27: {='DROP 2'!B74:G74} -> FORMARIZ | F27: M | G27: 1 | H27: 1 | I27: 49 | J27: DROP 2 | L27: DROP 2 | M27: 63 | O27: RUBINI | P27: 3
A28: DIEGUITO | D28: =D27+1 -> 27 | E28: {='DROP 2'!B75:G75} -> DOMINGUEZ | F28: L | G28: 2 | H28: 2 | I28: 63 | J28: DROP 2 | L28: DROP 5 | M28: 66 | O28: FORMARIZ | P28: 3
A29: DIRECTOR AMIGO JACO | D29: =D28+1 -> 28 | E29: {='DROP 2'!B76:G76} -> IÑIGO | F29: L | G29: 2 | H29: 1 | I29: 40 | J29: DROP 2 | L29: SUMMER DROP | M29: 38 | O29: IAGO AMIGO JACO | P29: 3
... A44: JOSE AMIGO JACO | D44: =D43+1 -> 43 | E44: {='DROP 2'!B91:G91} -> BARTA | F44: M | G44: 1 | H44: 1 | I44: 25 | J44: DROP 2 | L44: DROP 4 | M44: 77 | O44: AMIGO ANGEL | P44: 1
A45: JP | D45: =D44+1 -> 44 | E45: {='SUMMER DROP'!B65:G65} -> MUÑOZ | F45: L | G45: 2 | H45: 1 | I45: 19 | J45: SUMMER DROP | L45: SUMMER DROP | M45: 19 | O45: NACHO BENITO | P45: 1
A46: JUANMA | D46: =D45+1 -> 45 | E46: {='SUMMER DROP'!B66:G66} -> PETER | F46: L | G46: 2 | H46: 2 | I46: 38 | J46: SUMMER DROP | L46: CASAPE | M46: 169 | O46: ALVARO GOMEZ | P46: 1
A47: JUANTO | D47: =D46+1 -> 46 | E47: {='SUMMER DROP'!B67:G67} -> JUANMA | F47: L | G47: 2 | H47: 1 | I47: 19 | J47: SUMMER DROP | L47: DROP 1 | M47: 30 | O47: ALEX GARCIA | P47: 1
A48: LAURA PUIG | D48: =D47+1 -> 47 | E48: {='SUMMER DROP'!B68:G68} -> NICO RUIZ | F48: M | G48: 1 | H48: 2 | I48: 38 | J48: SUMMER DROP | L48: DROP 2 | M48: 29 | O48: ALEX DELCAUX | P48: 1
A49: LUCAS MARTINEZ | D49: =D48+1 -> 48 | E49: {='SUMMER DROP'!B69:G69} -> ASTARLOA | F49: L | G49: 2 | H49: 1 | I49: 19 | J49: SUMMER DROP | L49: DROP 4 | M49: 44 | O49: GABRIEL | P49: 1
A50: LUIS CANADA | D50: =D49+1 -> 49 | E50: {='SUMMER DROP'!B70:G70} -> RUBINI | F50: L | G50: 2 | H50: 1 | I50: 19 | J50: SUMMER DROP | L50: DROP 5 | M50: 66 | O50: JAIME RAMIREZ | P50: 1
A51: MARIO MIRON | D51: =D50+1 -> 50 | E51: {='SUMMER DROP'!B71:G71} -> PUIG AMIGO JACO | F51: M | G51: 1 | H51: 1 | I51: 19 | J51: SUMMER DROP | L51: LUIS CANADA | M51: 159 | O51: NATHAN | P51: 1
A52: MARQUINA | D52: =D51+1 -> 51 | E52: {='SUMMER DROP'!B72:G72} -> JUANTO | F52: M | G52: 1 | H52: 2 | I52: 38 | J52: SUMMER DROP | L52: A33 X NO ART | M52: 35 | O52: JAIME X | P52: 1
A53: MMEDRANO | D53: =D52+1 -> 52 | E53: {='SUMMER DROP'!B73:G73} -> NICO DIAMANTO | F53: M | G53: 1 | H53: 1 | I53: 19 | J53: SUMMER DROP | L53: DROP 1 | M53: 80 | O53: FELIX | P53: 1
A54: MONICA AMIGA JACO | D54: =D53+1 -> 53 | E54: {='SUMMER DROP'!B74:G74} -> DOMINGUEZ | F54: L | G54: 2 | H54: 1 | I54: 19 | J54: SUMMER DROP | L54: DROP 4 | M54: 44 | O54: JORGE CALVO | P54: 1
...

Sheet A33 (NEW)
B2: INVERSION | H2: INGRESOS | P2: GASTOS | AA2: COSTES GENERALES | AB2: €/UND | AC2: UNIDADES | AD2: IVA | AE2: € PER UND
H3: DROP | I3: DROP ANTERIOR | J3: PRESUPUESTO | K3: INGRESOS | L3: %VAR D/A | M3: %PPTO | P3: DROP | Q3: DROP ANTERIOR | R3: PRESUPUESTO | S3: GASTOS | T3: %VAR D/A | U3: %PPTO | AA3: Packaging | AB3: 148.63 | AC3: 100 | AE3: =IFERROR(AB3/AC3,"-") -> 1.4863
H4: 1 | I4: 0 | J4: ='D1'!C8 -> 1015 | K4: ='D1'!D8 -> 0 | L4: =IFERROR(IF(I4<0,-(K4/I4-1),K4/I4-1),"-") -> - | M4: =IFERROR(1+(K4-J4)/ABS(J4),"-") -> 0 | N4: =IF(M4>=1,3,IF(M4>=0.95,2,1)) -> 1 | P4: 1 | Q4: 0 | R4: ='D1'!C14 -> -824.1647 | S4: ='D1'!D14 -> -781.062 | T4: =IFERROR(IF(Q4>0,-(S4/Q4-1),S4/Q4-1),"-") -> - | U4: =IFERROR(1+(S4-R4)/ABS(R4),"-") -> 1.0522986 | V4: =IF(U4>=1,3,IF(U4>=0.95,2,1)) -> 3 | AA4: Etiquetas | AB4: 94.4 | AC4: 100 | AE4: =IFERROR(AB4/AC4,"-") -> 0.944
B5: BENEFICIO | H5: 2 | I5: =K4 -> 0 | L5: =IFERROR(IF(I5<0,-(K5/I5-1),K5/I5-1),"-") -> - | M5: =IFERROR(1+(K5-J5)/ABS(J5),"-") -> - | N5: =IF(M5>=1,3,IF(M5>=0.95,2,1)) -> 3 | P5: 2 | Q5: =S4 -> -781.062 | T5: =IFERROR(IF(Q5>0,-(S5/Q5-1),S5/Q5-1),"-") -> -1 | U5: =IFERROR(1+(S5-R5)/ABS(R5),"-") -> - | V5: =IF(U5>=1,3,IF(U5>=0.95,2,1)) -> 3 | AA5: ='A33'!$S$5 -> 0 | AC5: =#REF! -> #REF! | AD5: =IFERROR(((AB5*AC5)*0.21)/AC5,"-") -> - | AE5: =IFERROR(AB5/AC5,"-") -> -
H6: 3 | I6: =K5 -> 0 | L6: =IFERROR(IF(I6<0,-(K6/I6-1),K6/I6-1),"-") -> - | M6: =IFERROR(1+(K6-J6)/ABS(J6),"-") -> - | N6: =IF(M6>=1,3,IF(M6>=0.95,2,1)) -> 3 | P6: 3 | Q6: =S5 -> 0 | T6: =IFERROR(IF(Q6>0,-(S6/Q6-1),S6/Q6-1),"-") -> - | U6: =IFERROR(1+(S6-R6)/ABS(R6),"-") -> - | V6: =IF(U6>=1,3,IF(U6>=0.95,2,1)) -> 3 | AA6: ='A33'!$S$6 -> 0 | AC6: =#REF! -> #REF! | AD6: =IFERROR(((AB6*AC6)*0.21)/AC6,"-") -> - | AE6: =IFERROR(AB6/AC6,"-") -> -
H7: 4 | I7: =K6 -> 0 | L7: =IFERROR(IF(I7<0,-(K7/I7-1),K7/I7-1),"-") -> - | M7: =IFERROR(1+(K7-J7)/ABS(J7),"-") -> - | N7: =IF(M7>=1,3,IF(M7>=0.95,2,1)) -> 3 | P7: 4 | Q7: =S6 -> 0 | T7: =IFERROR(IF(Q7>0,-(S7/Q7-1),S7/Q7-1),"-") -> - | U7: =IFERROR(1+(S7-R7)/ABS(R7),"-") -> - | V7: =IF(U7>=1,3,IF(U7>=0.95,2,1)) -> 3 | AD7: =IFERROR(((AB7*AC7)*0.21)/AC7,"-") -> - | AE7: =IFERROR(AB7/AC7,"-") -> -
B8: COR | E8: =R27 -> 0.81198493 | H8: 5 | I8: =K7 -> 0 | L8: =IFERROR(IF(I8<0,-(K8/I8-1),K8/I8-1),"-") -> - | M8: =IFERROR(1+(K8-J8)/ABS(J8),"-") -> - | N8: =IF(M8>=1,3,IF(M8>=0.95,2,1)) -> 3 | P8: 5 | Q8: =S7 -> 0 | T8: =IFERROR(IF(Q8>0,-(S8/Q8-1),S8/Q8-1),"-") -> - | U8: =IFERROR(1+(S8-R8)/ABS(R8),"-") -> - | V8: =IF(U8>=1,3,IF(U8>=0.95,2,1)) -> 3 | AD8: =IFERROR(((AB8*AC8)*0.21)/AC8,"-") -> - | AE8: =IFERROR(AB8/AC8,"-") -> -
H9: 6 | I9: =K8 -> 0 | L9: =IFERROR(IF(I9<0,-(K9/I9-1),K9/I9-1),"-") -> - | M9: =IFERROR(1+(K9-J9)/ABS(J9),"-") -> - | N9: =IF(M9>=1,3,IF(M9>=0.95,2,1)) -> 3 | P9: 6 | Q9: =S8 -> 0 | T9: =IFERROR(IF(Q9>0,-(S9/Q9-1),S9/Q9-1),"-") -> - | U9: =IFERROR(1+(S9-R9)/ABS(R9),"-") -> - | V9: =IF(U9>=1,3,IF(U9>=0.95,2,1)) -> 3 | AA9: SERIGRAFIA TOTAL | AC9: =SUM(AC3:AC8) -> #REF!
H10: 7 | I10: =K9 -> 0 | L10: =IFERROR(IF(I10<0,-(K10/I10-1),K10/I10-1),"-") -> - | M10: =IFERROR(1+(K10-J10)/ABS(J10),"-") -> - | N10: =IF(M10>=1,3,IF(M10>=0.95,2,1)) -> 3 | P10: 7 | Q10: =S9 -> 0 | T10: =IFERROR(IF(Q10>0,-(S10/Q10-1),S10/Q10-1),"-") -> - | U10: =IFERROR(1+(S10-R10)/ABS(R10),"-") -> - | V10: =IF(U10>=1,3,IF(U10>=0.95,2,1)) -> 3
H11: 8 | I11: =K10 -> 0 | L11: =IFERROR(IF(I11<0,-(K11/I11-1),K11/I11-1),"-") -> - | M11: =IFERROR(1+(K11-J11)/ABS(J11),"-") -> - | N11: =IF(M11>=1,3,IF(M11>=0.95,2,1)) -> 3 | P11: 8 | Q11: =S10 -> 0 | T11: =IFERROR(IF(Q11>0,-(S11/Q11-1),S11/Q11-1),"-") -> - | U11: =IFERROR(1+(S11-R11)/ABS(R11),"-") -> - | V11: =IF(U11>=1,3,IF(U11>=0.95,2,1)) -> 3
H13: TOTAL | J13: =SUM(J4:J11) -> 1015 | K13: =SUM(K4:K11) -> 0 | M13: =IFERROR(1+(K13-J13)/ABS(J13),"-") -> 0 | N13: =IF(M13>=1,3,IF(M13>=0.95,2,1)) -> 1 | P13: TOTAL | R13: =SUM(R4:R11) -> -824.1647 | S13: =SUM(S4:S11) -> -781.062 | U13: =IFERROR(1+(S13-R13)/ABS(R13),"-") -> 1.0522986 | V13: =IF(U13>=1,3,IF(U13>=0.95,2,1)) -> 3
H16: BENEFICIO | P16: COR%
H17: DROP | I17: DROP ANTERIOR | J17: PRESUPUESTO | K17: BENEFICIO | L17: %VAR D/A | M17: %PPTO | P17: DROP | Q17: DROP ANTERIOR | R17: PRESUPUESTO | S17: COR% | T17: %VAR D/A | U17: %PPTO
H18: 1 | I18: 0 | J18: ='D1'!C17 -> 190.8353 | K18: ='D1'!D17 -> -781.062 | L18: =IFERROR(IF(AND(I18<0,K18>0),-(K18/I18-1),IF(AND(I18>0,K18<0),K18/I18-1,IF(AND(I18<0,K18<0),-(K18/I18-1),K18/I18-1))),"-") -> - | M18: =IFERROR(1+(K18-J18)/ABS(J18),"-") -> -4.0928591 | N18: =IF(M18>=1,3,IF(M18>=0.95,2,1)) -> 1 | P18: 1 | Q18: 0 | R18: ='D1'!C22 -> 0.81198493 | S18: ='D1'!D22 -> - | T18: =IFERROR(CONCATENATE(FIXED(100*(S18-Q18),1),"p.p."),"n.a.") -> n.a. | U18: =IFERROR(CONCATENATE(FIXED(100*(S18-R18),1),"p.p."),"n.a.") -> n.a. | V18: =IFERROR(IF(S18<R18,3,IF(U18>R18,1,2)),"-") -> 1 | W18: =ABS(R4/J4)-R18 -> 0 | X18: =ABS(S4/K4)-S18 -> #DIV/0!
H19: 2 | I19: =K18 -> -781.062 | L19: =IFERROR(IF(AND(I19<0,K19>0),-(K19/I19-1),IF(AND(I19>0,K19<0),K19/I19-1,IF(AND(I19<0,K19<0),-(K19/I19-1),K19/I19-1))),"-") -> -1 | M19: =IFERROR(1+(K19-J19)/ABS(J19),"-") -> - | N19: =IF(M19>=1,3,IF(M19>=0.95,2,1)) -> 3 | P19: 2 | Q19: =S18 -> - | T19: =IFERROR(CONCATENATE(FIXED(100*(S19-Q19),1),"p.p."),"n.a.") -> n.a. | U19: =IFERROR(CONCATENATE(FIXED(100*(S19-R19),1),"p.p."),"n.a.") -> 0,0p.p. | V19: =IFERROR(IF(S19<R19,3,IF(U19>R19,1,2)),"-") -> 1 | W19: =ABS(R5/J5)-R19 -> #DIV/0! | X19: =ABS(S5/K5)-S19 -> #DIV/0!
H20: 3 | I20: =K19 -> 0 | L20: =IFERROR(IF(AND(I20<0,K20>0),-(K20/I20-1),IF(AND(I20>0,K20<0),K20/I20-1,IF(AND(I20<0,K20<0),-(K20/I20-1),K20/I20-1))),"-") -> - | M20: =IFERROR(1+(K20-J20)/ABS(J20),"-") -> - | N20: =IF(M20>=1,3,IF(M20>=0.95,2,1)) -> 3 | P20: 3 | Q20: =S19 -> 0 | T20: =IFERROR(CONCATENATE(FIXED(100*(S20-Q20),1),"p.p."),"n.a.") -> 0,0p.p. | U20: =IFERROR(CONCATENATE(FIXED(100*(S20-R20),1),"p.p."),"n.a.") -> 0,0p.p. | V20: =IFERROR(IF(S20<R20,3,IF(U20>R20,1,2)),"-") -> 1 | W20: =ABS(R6/J6)-R20 -> #DIV/0! | X20: =ABS(S6/K6)-S20 -> #DIV/0!
H21: 4 | I21: =K20 -> 0 | L21: =IFERROR(IF(AND(I21<0,K21>0),-(K21/I21-1),IF(AND(I21>0,K21<0),K21/I21-1,IF(AND(I21<0,K21<0),-(K21/I21-1),K21/I21-1))),"-") -> - | M21: =IFERROR(1+(K21-J21)/ABS(J21),"-") -> - | N21: =IF(M21>=1,3,IF(M21>=0.95,2,1)) -> 3 | P21: 4 | Q21: =S20 -> 0 | T21: =IFERROR(CONCATENATE(FIXED(100*(S21-Q21),1),"p.p."),"n.a.") -> 0,0p.p. | U21: =IFERROR(CONCATENATE(FIXED(100*(S21-R21),1),"p.p."),"n.a.") -> 0,0p.p. | V21: =IFERROR(IF(S21<R21,3,IF(U21>R21,1,2)),"-") -> 1 | W21: =ABS(R7/J7)-R21 -> #DIV/0! | X21: =ABS(S7/K7)-S21 -> #DIV/0!
H22: 5 | I22: =K21 -> 0 | L22: =IFERROR(IF(AND(I22<0,K22>0),-(K22/I22-1),IF(AND(I22>0,K22<0),K22/I22-1,IF(AND(I22<0,K22<0),-(K22/I22-1),K22/I22-1))),"-") -> - | M22: =IFERROR(1+(K22-J22)/ABS(J22),"-") -> - | N22: =IF(M22>=1,3,IF(M22>=0.95,2,1)) -> 3 | P22: 5 | Q22: =S21 -> 0 | T22: =IFERROR(CONCATENATE(FIXED(100*(S22-Q22),1),"p.p."),"n.a.") -> 0,0p.p. | U22: =IFERROR(CONCATENATE(FIXED(100*(S22-R22),1),"p.p."),"n.a.") -> 0,0p.p. | V22: =IFERROR(IF(S22<R22,3,IF(U22>R22,1,2)),"-") -> 1 | W22: =ABS(R8/J8)-R22 -> #DIV/0! | X22: =ABS(S8/K8)-S22 -> #DIV/0!
H23: 6 | I23: =K22 -> 0 | L23: =IFERROR(IF(AND(I23<0,K23>0),-(K23/I23-1),IF(AND(I23>0,K23<0),K23/I23-1,IF(AND(I23<0,K23<0),-(K23/I23-1),K23/I23-1))),"-") -> - | M23: =IFERROR(1+(K23-J23)/ABS(J23),"-") -> - | N23: =IF(M23>=1,3,IF(M23>=0.95,2,1)) -> 3 | P23: 6 | Q23: =S22 -> 0 | T23: =IFERROR(CONCATENATE(FIXED(100*(S23-Q23),1),"p.p."),"n.a.") -> 0,0p.p. | U23: =IFERROR(CONCATENATE(FIXED(100*(S23-R23),1),"p.p."),"n.a.") -> 0,0p.p. | V23: =IFERROR(IF(S23<R23,3,IF(U23>R23,1,2)),"-") -> 1 | W23: =ABS(R9/J9)-R23 -> #DIV/0! | X23: =ABS(S9/K9)-S23 -> #DIV/0!
H24: 7 | I24: =K23 -> 0 | L24: =IFERROR(IF(AND(I24<0,K24>0),-(K24/I24-1),IF(AND(I24>0,K24<0),K24/I24-1,IF(AND(I24<0,K24<0),-(K24/I24-1),K24/I24-1))),"-") -> - | M24: =IFERROR(1+(K24-J24)/ABS(J24),"-") -> - | N24: =IF(M24>=1,3,IF(M24>=0.95,2,1)) -> 3 | P24: 7 | Q24: =S23 -> 0 | T24: =IFERROR(CONCATENATE(FIXED(100*(S24-Q24),1),"p.p."),"n.a.") -> 0,0p.p. | U24: =IFERROR(CONCATENATE(FIXED(100*(S24-R24),1),"p.p."),"n.a.") -> 0,0p.p. | V24: =IFERROR(IF(S24<R24,3,IF(U24>R24,1,2)),"-") -> 1 | W24: =ABS(R10/J10)-R24 -> #DIV/0! | X24: =ABS(S10/K10)-S24 -> #DIV/0!
H25: 8 | I25: =K24 -> 0 | L25: =IFERROR(IF(AND(I25<0,K25>0),-(K25/I25-1),IF(AND(I25>0,K25<0),K25/I25-1,IF(AND(I25<0,K25<0),-(K25/I25-1),K25/I25-1))),"-") -> - | M25: =IFERROR(1+(K25-J25)/ABS(J25),"-") -> - | N25: =IF(M25>=1,3,IF(M25>=0.95,2,1)) -> 3 | P25: 8 | Q25: =S24 -> 0 | T25: =IFERROR(CONCATENATE(FIXED(100*(S25-Q25),1),"p.p."),"n.a.") -> 0,0p.p. | U25: =IFERROR(CONCATENATE(FIXED(100*(S25-R25),1),"p.p."),"n.a.") -> 0,0p.p. | V25: =IFERROR(IF(S25<R25,3,IF(U25>R25,1,2)),"-") -> 1 | W25: =ABS(R11/J11)-R25 -> #DIV/0! | X25: =ABS(S11/K11)-S25 -> #DIV/0!
H27: TOTAL | J27: =SUM(J18:J25) -> 190.8353 | K27: =SUM(K18:K25) -> -781.062 | M27: =IFERROR(1+(K27-J27)/ABS(J27),"-") -> -4.0928591 | N27: =IF(M27>=1,3,IF(M27>=0.95,2,1)) -> 1 | P27: TOTAL | R27: =ABS(R13/J13) -> 0.81198493 | S27: =ABS(S13/K13) -> #DIV/0! | U27: =IFERROR(CONCATENATE(FIXED(100*(S27-R27),1),"p.p."),"n.a.") -> n.a. | V27: =IFERROR(IF(S27<R27,3,IF(U27>R27,1,2)),"-") -> - | W27: =ABS(R13/J13)-R27 -> 0 | X27: =ABS(S13/K13)-S27 -> #DIV/0!
H30: UNIDADES
H31: DROP | I31: DROP ANTERIOR | J31: PRESUPUESTO | K31: UNIDADES | L31: %VAR D/A | M31: %PPTO
H32: 1 | I32: 0 | J32: ='D1'!AH9 -> 29 | K32: ='D1'!O27 -> 0 | L32: =IFERROR(IF(AND(I32<0,K32>0),-(K32/I32-1),IF(AND(I32>0,K32<0),K32/I32-1,IF(AND(I32<0,K32<0),-(K32/I32-1),K32/I32-1))),"-") -> - | M32: =IFERROR(1+(K32-J32)/ABS(J32),"-") -> 0 | N32: =IF(M32>=1,3,IF(M32>=0.95,2,1)) -> 1
H33: 2 | I33: =K32 -> 0 | L33: =IFERROR(IF(AND(I33<0,K33>0),-(K33/I33-1),IF(AND(I33>0,K33<0),K33/I33-1,IF(AND(I33<0,K33<0),-(K33/I33-1),K33/I33-1))),"-") -> - | M33: =IFERROR(1+(K33-J33)/ABS(J33),"-") -> - | N33: =IF(M33>=1,3,IF(M33>=0.95,2,1)) -> 3
H34: 3 | I34: =K33 -> 0 | L34: =IFERROR(IF(AND(I34<0,K34>0),-(K34/I34-1),IF(AND(I34>0,K34<0),K34/I34-1,IF(AND(I34<0,K34<0),-(K34/I34-1),K34/I34-1))),"-") -> - | M34: =IFERROR(1+(K34-J34)/ABS(J34),"-") -> - | N34: =IF(M34>=1,3,IF(M34>=0.95,2,1)) -> 3
H35: 4 | I35: =K34 -> 0 | L35: =IFERROR(IF(AND(I35<0,K35>0),-(K35/I35-1),IF(AND(I35>0,K35<0),K35/I35-1,IF(AND(I35<0,K35<0),-(K35/I35-1),K35/I35-1))),"-") -> - | M35: =IFERROR(1+(K35-J35)/ABS(J35),"-") -> - | N35: =IF(M35>=1,3,IF(M35>=0.95,2,1)) -> 3
H36: 5 | I36: =K35 -> 0 | L36: =IFERROR(IF(AND(I36<0,K36>0),-(K36/I36-1),IF(AND(I36>0,K36<0),K36/I36-1,IF(AND(I36<0,K36<0),-(K36/I36-1),K36/I36-1))),"-") -> - | M36: =IFERROR(1+(K36-J36)/ABS(J36),"-") -> - | N36: =IF(M36>=1,3,IF(M36>=0.95,2,1)) -> 3
H37: 6 | I37: =K36 -> 0 | L37: =IFERROR(IF(AND(I37<0,K37>0),-(K37/I37-1),IF(AND(I37>0,K37<0),K37/I37-1,IF(AND(I37<0,K37<0),-(K37/I37-1),K37/I37-1))),"-") -> - | M37: =IFERROR(1+(K37-J37)/ABS(J37),"-") -> - | N37: =IF(M37>=1,3,IF(M37>=0.95,2,1)) -> 3
H38: 7 | I38: =K37 -> 0 | L38: =IFERROR(IF(AND(I38<0,K38>0),-(K38/I38-1),IF(AND(I38>0,K38<0),K38/I38-1,IF(AND(I38<0,K38<0),-(K38/I38-1),K38/I38-1))),"-") -> - | M38: =IFERROR(1+(K38-J38)/ABS(J38),"-") -> - | N38: =IF(M38>=1,3,IF(M38>=0.95,2,1)) -> 3
H39: 8 | I39: =K38 -> 0 | L39: =IFERROR(IF(AND(I39<0,K39>0),-(K39/I39-1),IF(AND(I39>0,K39<0),K39/I39-1,IF(AND(I39<0,K39<0),-(K39/I39-1),K39/I39-1))),"-") -> - | M39: =IFERROR(1+(K39-J39)/ABS(J39),"-") -> - | N39: =IF(M39>=1,3,IF(M39>=0.95,2,1)) -> 3
H41: TOTAL | J41: =SUM(J32:J39) -> 29 | K41: =SUM(K32:K39) -> 0 | M41: =IFERROR(1+(K41-J41)/ABS(J41),"-") -> 0 | N41: =IF(M41>=1,3,IF(M41>=0.95,2,1)) -> 1

Sheet A33
B2: INGRESOS | J2: GASTOS
B3: DROP | C3: DROP ANTERIOR | D3: PRESUPUESTO | E3: INGRESOS | F3: %VAR D/A | G3: %PPTO | J3: DROP | K3: DROP ANTERIOR | L3: PRESUPUESTO | M3: GASTOS | N3: %VAR D/A | O3: %PPTO
B4: 1 | C4: 0 | D4: ='DROP 1'!C6 -> 1130 | E4: ='DROP 1'!D6 -> 1049 | F4: =IFERROR(IF(C4<0,-(E4/C4-1),E4/C4-1),"-") -> - | G4: =IFERROR(1+(E4-D4)/ABS(D4),"-") -> 0.92831858 | H4: =IF(G4>=1,3,IF(G4>=0.95,2,1)) -> 1 | J4: 1 | K4: 0 | L4: ='DROP 1'!C14 -> -838.1 | M4: ='DROP 1'!D14 -> -838.1 | N4: =IFERROR(IF(K4>0,-(M4/K4-1),M4/K4-1),"-") -> - | O4: =IFERROR(1+(M4-L4)/ABS(L4),"-") -> 1 | P4: =IF(O4>=1,3,IF(O4>=0.95,2,1)) -> 3
B5: 2 | C5: =E4 -> 1049 | D5: ='DROP 2'!C8 -> 1318 | E5: ='DROP 2'!D8 -> 1304 | F5: =IFERROR(IF(C5<0,-(E5/C5-1),E5/C5-1),"-") -> 0.24308866 | G5: =IFERROR(1+(E5-D5)/ABS(D5),"-") -> 0.98937785 | H5: =IF(G5>=1,3,IF(G5>=0.95,2,1)) -> 2 | J5: 2 | K5: =M4 -> -838.1 | L5: ='DROP 2'!C14 -> -1261.695 | M5: ='DROP 2'!D14 -> -1261.695 | N5: =IFERROR(IF(K5>0,-(M5/K5-1),M5/K5-1),"-") -> 0.50542298 | O5: =IFERROR(1+(M5-L5)/ABS(L5),"-") -> 1 | P5: =IF(O5>=1,3,IF(O5>=0.95,2,1)) -> 3
B6: SUMMER DROP | C6: =E5 -> 1304 | D6: ='SUMMER DROP'!C8 -> 494 | E6: ='SUMMER DROP'!D8 -> 494 | F6: =IFERROR(IF(C6<0,-(E6/C6-1),E6/C6-1),"-") -> -0.62116564 | G6: =IFERROR(1+(E6-D6)/ABS(D6),"-") -> 1 | H6: =IF(G6>=1,3,IF(G6>=0.95,2,1)) -> 3 | J6: SUMMER DROP | K6: =M5 -> -1261.695 | L6: ='SUMMER DROP'!C14 -> -211.17 | M6: ='SUMMER DROP'!D14 -> -211.17 | N6: =IFERROR(IF(K6>0,-(M6/K6-1),M6/K6-1),"-") -> -0.83262991 | O6: =IFERROR(1+(M6-L6)/ABS(L6),"-") -> 1 | P6: =IF(O6>=1,3,IF(O6>=0.95,2,1)) -> 3
B7: A33 X NO ART | C7: =E6 -> 494 | D7: ='A33 X NO ART'!C8 -> 875 | E7: ='A33 X NO ART'!D8 -> 830 | F7: =IFERROR(IF(C7<0,-(E7/C7-1),E7/C7-1),"-") -> 0.68016194 | G7: =IFERROR(1+(E7-D7)/ABS(D7),"-") -> 0.94857143 | H7: =IF(G7>=1,3,IF(G7>=0.95,2,1)) -> 1 | J7: A33 X NO ART | K7: =M6 -> -211.17 | L7: ='A33 X NO ART'!C14 -> -790.83 | M7: ='A33 X NO ART'!D14 -> -790.83 | N7: =IFERROR(IF(K7>0,-(M7/K7-1),M7/K7-1),"-") -> 2.7449922 | O7: =IFERROR(1+(M7-L7)/ABS(L7),"-") -> 1 | P7: =IF(O7>=1,3,IF(O7>=0.95,2,1)) -> 3
B8: 3 | C8: =E7 -> 830 | D8: ='DROP 3'!C8 -> 1014 | E8: ='DROP 3'!D8 -> 644 | F8: =IFERROR(IF(C8<0,-(E8/C8-1),E8/C8-1),"-") -> -0.22409639 | G8: =IFERROR(1+(E8-D8)/ABS(D8),"-") -> 0.63510848 | H8: =IF(G8>=1,3,IF(G8>=0.95,2,1)) -> 1 | J8: 3 | K8: =M7 -> -790.83 | L8: ='DROP 3'!C14 -> -948.71 | M8: ='DROP 3'!D14 -> -948.71 | N8: =IFERROR(IF(K8>0,-(M8/K8-1),M8/K8-1),"-") -> 0.19963835 | O8: =IFERROR(1+(M8-L8)/ABS(L8),"-") -> 1 | P8: =IF(O8>=1,3,IF(O8>=0.95,2,1)) -> 3
B9: 4 | C9: =E8 -> 644 | D9: ='DROP 4'!C8 -> 1476 | E9: ='DROP 4'!D8 -> 1267 | F9: =IFERROR(IF(C9<0,-(E9/C9-1),E9/C9-1),"-") -> 0.9673913 | G9: =IFERROR(1+(E9-D9)/ABS(D9),"-") -> 0.85840108 | H9: =IF(G9>=1,3,IF(G9>=0.95,2,1)) -> 1 | J9: 4 | K9: =M8 -> -948.71 | L9: ='DROP 4'!C14 -> -1318.04 | M9: ='DROP 4'!D14 -> -1318.04 | N9: =IFERROR(IF(K9>0,-(M9/K9-1),M9/K9-1),"-") -> 0.38929705 | O9: =IFERROR(1+(M9-L9)/ABS(L9),"-") -> 1 | P9: =IF(O9>=1,3,IF(O9>=0.95,2,1)) -> 3
B10: 5 | C10: =E9 -> 1267 | D10: ='DROP 5'!C8 -> 1221 | E10: ='DROP 5'!D8 -> 363 | F10: =IFERROR(IF(C10<0,-(E10/C10-1),E10/C10-1),"-") -> -0.71349645 | G10: =IFERROR(1+(E10-D10)/ABS(D10),"-") -> 0.2972973 | H10: =IF(G10>=1,3,IF(G10>=0.95,2,1)) -> 1 | J10: 5 | K10: =M9 -> -1318.04 | L10: ='DROP 5'!C14 -> -942.27 | M10: ='DROP 5'!D14 -> -942.27 | N10: =IFERROR(IF(K10>0,-(M10/K10-1),M10/K10-1),"-") -> -0.28509757 | O10: =IFERROR(1+(M10-L10)/ABS(L10),"-") -> 1 | P10: =IF(O10>=1,3,IF(O10>=0.95,2,1)) -> 3
B11: 6 | C11: =E10 -> 363 | F11: =IFERROR(IF(C11<0,-(E11/C11-1),E11/C11-1),"-") -> -1 | G11: =IFERROR(1+(E11-D11)/ABS(D11),"-") -> - | H11: =IF(G11>=1,3,IF(G11>=0.95,2,1)) -> 3 | J11: 6 | K11: =M10 -> -942.27 | N11: =IFERROR(IF(K11>0,-(M11/K11-1),M11/K11-1),"-") -> -1 | O11: =IFERROR(1+(M11-L11)/ABS(L11),"-") -> - | P11: =IF(O11>=1,3,IF(O11>=0.95,2,1)) -> 3
B13: TOTAL | D13: =SUM(D4:D11) -> 7528 | E13: =SUM(E4:E11) -> 5951 | G13: =IFERROR(1+(E13-D13)/ABS(D13),"-") -> 0.79051541 | H13: =IF(G13>=1,3,IF(G13>=0.95,2,1)) -> 1 | J13: TOTAL | L13: =SUM(L4:L11) -> -6310.815 | M13: =SUM(M4:M11) -> -6310.815 | O13: =IFERROR(1+(M13-L13)/ABS(L13),"-") -> 1 | P13: =IF(O13>=1,3,IF(O13>=0.95,2,1)) -> 3
B16: BENEFICIO | J16: COR%
B17: DROP | C17: DROP ANTERIOR | D17: PRESUPUESTO | E17: BENEFICIO | F17: %VAR D/A | G17: %PPTO | J17: DROP | K17: DROP ANTERIOR | L17: PRESUPUESTO | M17: COR% | N17: %VAR D/A | O17: %PPTO
B18: 1 | C18: 0 | D18: ='DROP 1'!C17 -> 291.9 | E18: ='DROP 1'!D17 -> 210.9 | F18: =IFERROR(IF(AND(C18<0,E18>0),-(E18/C18-1),IF(AND(C18>0,E18<0),E18/C18-1,IF(AND(C18<0,E18<0),-(E18/C18-1),E18/C18-1))),"-") -> - | G18: =IFERROR(1+(E18-D18)/ABS(D18),"-") -> 0.72250771 | H18: =IF(G18>=1,3,IF(G18>=0.95,2,1)) -> 1 | J18: 1 | K18: 0 | L18: ='DROP 1'!C20 -> 0.74168142 | M18: ='DROP 1'!D20 -> 0.79895138 | N18: =IFERROR(CONCATENATE(FIXED(100*(M18-K18),1),"p.p."),"n.a.") -> 79,9p.p. | O18: =IFERROR(CONCATENATE(FIXED(100*(M18-L18),1),"p.p."),"n.a.") -> 5,7p.p. | P18: =IFERROR(IF(M18<L18,3,IF(O18>L18,1,2)),"-") -> 1 | Q18: =ABS(L4/D4)-L18 -> 0 | R18: =ABS(M4/E4)-M18 -> 0
B19: 2 | C19: =E18 -> 210.9 | D19: ='DROP 2'!C17 -> 56.305 | E19: ='DROP 2'!D17 -> 42.305 | F19: =IFERROR(IF(AND(C19<0,E19>0),-(E19/C19-1),IF(AND(C19>0,E19<0),E19/C19-1,IF(AND(C19<0,E19<0),-(E19/C19-1),E19/C19-1))),"-") -> -0.7994073 | G19: =IFERROR(1+(E19-D19)/ABS(D19),"-") -> 0.75135423 | H19: =IF(G19>=1,3,IF(G19>=0.95,2,1)) -> 1 | J19: 2 | K19: =M18 -> 0.79895138 | L19: ='DROP 2'!C20 -> 0.95727997 | M19: ='DROP 2'!D20 -> 0.96755752 | N19: =IFERROR(CONCATENATE(FIXED(100*(M19-K19),1),"p.p."),"n.a.") -> 16,9p.p. | O19: =IFERROR(CONCATENATE(FIXED(100*(M19-L19),1),"p.p."),"n.a.") -> 1,0p.p. | P19: =IFERROR(IF(M19<L19,3,IF(O19>L19,1,2)),"-") -> 1 | Q19: =ABS(L5/D5)-L19 -> 0 | R19: =ABS(M5/E5)-M19 -> 0
B20: SUMMER DROP | C20: =E19 -> 42.305 | D20: ='SUMMER DROP'!C17 -> 282.83 | E20: ='SUMMER DROP'!D17 -> 282.83 | F20: =IFERROR(IF(AND(C20<0,E20>0),-(E20/C20-1),IF(AND(C20>0,E20<0),E20/C20-1,IF(AND(C20<0,E20<0),-(E20/C20-1),E20/C20-1))),"-") -> 5.6854982 | G20: =IFERROR(1+(E20-D20)/ABS(D20),"-") -> 1 | H20: =IF(G20>=1,3,IF(G20>=0.95,2,1)) -> 3 | J20: SUMMER DROP | K20: =M19 -> 0.96755752 | L20: ='SUMMER DROP'!C20 -> 0.42746964 | M20: ='SUMMER DROP'!D20 -> 0.42746964 | N20: =IFERROR(CONCATENATE(FIXED(100*(M20-K20),1),"p.p."),"n.a.") -> -54,0p.p. | O20: =IFERROR(CONCATENATE(FIXED(100*(M20-L20),1),"p.p."),"n.a.") -> 0,0p.p. | P20: =IFERROR(IF(M20<L20,3,IF(O20>L20,1,2)),"-") -> 1 | Q20: =ABS(L6/D6)-L20 -> 0 | R20: =ABS(M6/E6)-M20 -> 0
B21: A33 X NO ART | C21: =E20 -> 282.83 | D21: ='A33 X NO ART'!C17 -> 84.17 | E21: ='A33 X NO ART'!D17 -> 39.17 | F21: =IFERROR(IF(AND(C21<0,E21>0),-(E21/C21-1),IF(AND(C21>0,E21<0),E21/C21-1,IF(AND(C21<0,E21<0),-(E21/C21-1),E21/C21-1))),"-") -> -0.86150691 | G21: =IFERROR(1+(E21-D21)/ABS(D21),"-") -> 0.46536771 | H21: =IF(G21>=1,3,IF(G21>=0.95,2,1)) -> 1 | J21: A33 X NO ART | K21: =M20 -> 0.42746964 | L21: ='A33 X NO ART'!C20 -> 0.90380571 | M21: ='A33 X NO ART'!D20 -> 0.95280723 | N21: =IFERROR(CONCATENATE(FIXED(100*(M21-K21),1),"p.p."),"n.a.") -> 52,5p.p. | O21: =IFERROR(CONCATENATE(FIXED(100*(M21-L21),1),"p.p."),"n.a.") -> 4,9p.p. | P21: =IFERROR(IF(M21<L21,3,IF(O21>L21,1,2)),"-") -> 1 | Q21: =ABS(L7/D7)-L21 -> 0 | R21: =ABS(M7/E7)-M21 -> 0
B22: 3 | C22: =E21 -> 39.17 | D22: ='DROP 3'!C17 -> 65.29 | E22: ='DROP 3'!D17 -> -304.71 | F22: =IFERROR(IF(AND(C22<0,E22>0),-(E22/C22-1),IF(AND(C22>0,E22<0),E22/C22-1,IF(AND(C22<0,E22<0),-(E22/C22-1),E22/C22-1))),"-") -> -8.7791677 | G22: =IFERROR(1+(E22-D22)/ABS(D22),"-") -> -4.667024 | H22: =IF(G22>=1,3,IF(G22>=0.95,2,1)) -> 1 | J22: 3 | K22: =M21 -> 0.95280723 | L22: ='DROP 3'!C20 -> 0.93561144 | M22: ='DROP 3'!D20 -> 1.4731522 | N22: =IFERROR(CONCATENATE(FIXED(100*(M22-K22),1),"p.p."),"n.a.") -> 52,0p.p. | O22: =IFERROR(CONCATENATE(FIXED(100*(M22-L22),1),"p.p."),"n.a.") -> 53,8p.p. | P22: =IFERROR(IF(M22<L22,3,IF(O22>L22,1,2)),"-") -> 1 | Q22: =ABS(L8/D8)-L22 -> 0 | R22: =ABS(M8/E8)-M22 -> 0
B23: 4 | C23: =E22 -> -304.71 | D23: ='DROP 4'!C17 -> 157.96 | E23: ='DROP 4'!D17 -> -51.04 | F23: =IFERROR(IF(AND(C23<0,E23>0),-(E23/C23-1),IF(AND(C23>0,E23<0),E23/C23-1,IF(AND(C23<0,E23<0),-(E23/C23-1),E23/C23-1))),"-") -> 0.83249647 | G23: =IFERROR(1+(E23-D23)/ABS(D23),"-") -> -0.32311978 | H23: =IF(G23>=1,3,IF(G23>=0.95,2,1)) -> 1 | J23: 4 | K23: =M22 -> 1.4731522 | L23: ='DROP 4'!C20 -> 0.89298103 | M23: ='DROP 4'!D20 -> 1.0402841 | N23: =IFERROR(CONCATENATE(FIXED(100*(M23-K23),1),"p.p."),"n.a.") -> -43,3p.p. | O23: =IFERROR(CONCATENATE(FIXED(100*(M23-L23),1),"p.p."),"n.a.") -> 14,7p.p. | P23: =IFERROR(IF(M23<L23,3,IF(O23>L23,1,2)),"-") -> 1 | Q23: =ABS(L9/D9)-L23 -> 0 | R23: =ABS(M9/E9)-M23 -> 0
B24: 5 | C24: =E23 -> -51.04 | D24: ='DROP 5'!C17 -> 278.73 | E24: ='DROP 5'!D17 -> -579.27 | F24: =IFERROR(IF(AND(C24<0,E24>0),-(E24/C24-1),IF(AND(C24>0,E24<0),E24/C24-1,IF(AND(C24<0,E24<0),-(E24/C24-1),E24/C24-1))),"-") -> -10.349334 | G24: =IFERROR(1+(E24-D24)/ABS(D24),"-") -> -2.0782478 | H24: =IF(G24>=1,3,IF(G24>=0.95,2,1)) -> 1 | J24: 5 | K24: =M23 -> 1.0402841 | L24: ='DROP 5'!C20 -> 0.7717199 | M24: ='DROP 5'!D20 -> 2.5957851 | N24: =IFERROR(CONCATENATE(FIXED(100*(M24-K24),1),"p.p."),"n.a.") -> 155,6p.p. | O24: =IFERROR(CONCATENATE(FIXED(100*(M24-L24),1),"p.p."),"n.a.") -> 182,4p.p. | P24: =IFERROR(IF(M24<L24,3,IF(O24>L24,1,2)),"-") -> 1 | Q24: =ABS(L10/D10)-L24 -> 0 | R24: =ABS(M10/E10)-M24 -> 0
B25: 6 | C25: =E24 -> -579.27 | F25: =IFERROR(IF(AND(C25<0,E25>0),-(E25/C25-1),IF(AND(C25>0,E25<0),E25/C25-1,IF(AND(C25<0,E25<0),-(E25/C25-1),E25/C25-1))),"-") -> -1 | G25: =IFERROR(1+(E25-D25)/ABS(D25),"-") -> - | H25: =IF(G25>=1,3,IF(G25>=0.95,2,1)) -> 3 | J25: 6 | K25: =M24 -> 2.5957851 | N25: =IFERROR(CONCATENATE(FIXED(100*(M25-K25),1),"p.p."),"n.a.") -> -259,6p.p. | O25: =IFERROR(CONCATENATE(FIXED(100*(M25-L25),1),"p.p."),"n.a.") -> 0,0p.p. | P25: =IFERROR(IF(M25<L25,3,IF(O25>L25,1,2)),"-") -> 1 | Q25: =ABS(L11/D11)-L25 -> #DIV/0! | R25: =ABS(M11/E11)-M25 -> #DIV/0!
B27: TOTAL | D27: =SUM(D18:D25) -> 1217.185 | E27: =SUM(E18:E25) -> -359.815 | G27: =IFERROR(1+(E27-D27)/ABS(D27),"-") -> -0.29561242 | H27: =IF(G27>=1,3,IF(G27>=0.95,2,1)) -> 1 | J27: TOTAL | L27: =ABS(L13/D13) -> 0.8383123 | M27: =ABS(M13/E13) -> 1.0604629 | O27: =IFERROR(CONCATENATE(FIXED(100*(M27-L27),1),"p.p."),"n.a.") -> 22,2p.p. | P27: =IFERROR(IF(M27<L27,3,IF(O27>L27,1,2)),"-") -> 1 | Q27: =ABS(L13/D13)-L27 -> 0 | R27: =ABS(M13/E13)-M27 -> 0
B30: UNIDADES
B31: DROP | C31: DROP ANTERIOR | D31: PRESUPUESTO | E31: UNIDADES | F31: %VAR D/A | G31: %PPTO
B32: 1 | C32: 0 | D32: ='DROP 1'!T9 -> 26 | E32: ='DROP 1'!K24 -> 25 | F32: =IFERROR(IF(AND(C32<0,E32>0),-(E32/C32-1),IF(AND(C32>0,E32<0),E32/C32-1,IF(AND(C32<0,E32<0),-(E32/C32-1),E32/C32-1))),"-") -> - | G32: =IFERROR(1+(E32-D32)/ABS(D32),"-") -> 0.96153846 | H32: =IF(G32>=1,3,IF(G32>=0.95,2,1)) -> 2
B33: 2 | C33: =E32 -> 25 | D33: ='DROP 2'!T9+'DROP 2'!T18 -> 38 | E33: ='DROP 2'!K24 -> 38 | F33: =IFERROR(IF(AND(C33<0,E33>0),-(E33/C33-1),IF(AND(C33>0,E33<0),E33/C33-1,IF(AND(C33<0,E33<0),-(E33/C33-1),E33/C33-1))),"-") -> 0.52 | G33: =IFERROR(1+(E33-D33)/ABS(D33),"-") -> 1 | H33: =IF(G33>=1,3,IF(G33>=0.95,2,1)) -> 3
B34: SUMMER DROP | C34: =E33 -> 38 | D34: ='SUMMER DROP'!T9 -> 26 | E34: ='SUMMER DROP'!K24 -> 26 | F34: =IFERROR(IF(AND(C34<0,E34>0),-(E34/C34-1),IF(AND(C34>0,E34<0),E34/C34-1,IF(AND(C34<0,E34<0),-(E34/C34-1),E34/C34-1))),"-") -> -0.31578947 | G34: =IFERROR(1+(E34-D34)/ABS(D34),"-") -> 1 | H34: =IF(G34>=1,3,IF(G34>=0.95,2,1)) -> 3
B35: A33 X NO ART | C35: =E34 -> 26 | D35: ='A33 X NO ART'!T9 -> 25 | E35: ='A33 X NO ART'!K24 -> 25 | F35: =IFERROR(IF(AND(C35<0,E35>0),-(E35/C35-1),IF(AND(C35>0,E35<0),E35/C35-1,IF(AND(C35<0,E35<0),-(E35/C35-1),E35/C35-1))),"-") -> -0.038461538 | G35: =IFERROR(1+(E35-D35)/ABS(D35),"-") -> 1 | H35: =IF(G35>=1,3,IF(G35>=0.95,2,1)) -> 3
B36: 3 | C36: =E35 -> 25 | D36: ='DROP 3'!T9 -> 22 | E36: ='DROP 3'!K24 -> 14 | F36: =IFERROR(IF(AND(C36<0,E36>0),-(E36/C36-1),IF(AND(C36>0,E36<0),E36/C36-1,IF(AND(C36<0,E36<0),-(E36/C36-1),E36/C36-1))),"-") -> -0.44 | G36: =IFERROR(1+(E36-D36)/ABS(D36),"-") -> 0.63636364 | H36: =IF(G36>=1,3,IF(G36>=0.95,2,1)) -> 1
B37: 4 | C37: =E36 -> 14 | D37: ='DROP 4'!T9 -> 39 | E37: ='DROP 4'!K24 -> 39 | F37: =IFERROR(IF(AND(C37<0,E37>0),-(E37/C37-1),IF(AND(C37>0,E37<0),E37/C37-1,IF(AND(C37<0,E37<0),-(E37/C37-1),E37/C37-1))),"-") -> 1.7857143 | G37: =IFERROR(1+(E37-D37)/ABS(D37),"-") -> 1 | H37: =IF(G37>=1,3,IF(G37>=0.95,2,1)) -> 3
B38: 5 | C38: =E37 -> 39 | D38: ='DROP 5'!T9 -> 37 | E38: ='DROP 5'!K24 -> 27 | F38: =IFERROR(IF(AND(C38<0,E38>0),-(E38/C38-1),IF(AND(C38>0,E38<0),E38/C38-1,IF(AND(C38<0,E38<0),-(E38/C38-1),E38/C38-1))),"-") -> -0.30769231 | G38: =IFERROR(1+(E38-D38)/ABS(D38),"-") -> 0.72972973 | H38: =IF(G38>=1,3,IF(G38>=0.95,2,1)) -> 1
B39: 6 | C39: =E38 -> 27 | F39: =IFERROR(IF(AND(C39<0,E39>0),-(E39/C39-1),IF(AND(C39>0,E39<0),E39/C39-1,IF(AND(C39<0,E39<0),-(E39/C39-1),E39/C39-1))),"-") -> -1 | G39: =IFERROR(1+(E39-D39)/ABS(D39),"-") -> - | H39: =IF(G39>=1,3,IF(G39>=0.95,2,1)) -> 3
B41: TOTAL | D41: =SUM(D32:D39) -> 213 | E41: =SUM(E32:E39) -> 194 | G41: =IFERROR(1+(E41-D41)/ABS(D41),"-") -> 0.91079812 | H41: =IF(G41>=1,3,IF(G41>=0.95,2,1)) -> 1

Sheet BASE
B2: DROP X | S2: BLANKS 1 | T2: UND€ | U2: M | V2: L | W2: XL | X2: UNIDADES | Y2: EXTRA | Z2: € PER UND | AA2: TOTAL | AC2: INGRESOS FINALES | AD2: PRECIO | AE2: M | AF2: L | AG2: XL | AH2: UNIDADES | AI2: TOTAL
X3: =SUM(U3:W3) -> 0 | Y3: =IFERROR($AA$12/$X$9,"-") -> - | Z3: =IFERROR(T3+Y3,"-") -> - | AA3: =IFERROR(X3*Z3,"-") -> - | AC3: =$S$3 -> 0 | AD3: =T40 -> 0 | AE3: =U40-U49 -> 0 | AF3: =V40-V49 -> 0 | AG3: =W40-W49 -> 0 | AH3: =SUM(AE3:AG3) -> 0 | AI3: =IFERROR(AD3*AH3,"-") -> 0
X4: =SUM(U4:W4) -> 0 | Y4: =IFERROR($AA$12/$X$9,"-") -> - | Z4: =IFERROR(T4+Y4,"-") -> - | AA4: =IFERROR(X4*Z4,"-") -> - | AC4: =$S$4 -> 0 | AD4: =T41 -> 0 | AE4: =U41-U50 -> 0 | AF4: =V41-V50 -> 0 | AG4: =W41-W50 -> 0 | AH4: =SUM(AE4:AG4) -> 0 | AI4: =IFERROR(AD4*AH4,"-") -> 0
C5: PPTO | D5: REAL | X5: =SUM(U5:W5) -> 0 | Y5: =IFERROR($AA$12/$X$9,"-") -> - | Z5: =IFERROR(T5+Y5,"-") -> - | AA5: =IFERROR(X5*Z5,"-") -> - | AC5: =$S$5 -> 0 | AD5: =T42 -> 0 | AE5: =U42-U51 -> 0 | AF5: =V42-V51 -> 0 | AG5: =W42-W51 -> 0 | AH5: =SUM(AE5:AG5) -> 0 | AI5: =IFERROR(AD5*AH5,"-") -> 0
B6: INGRESOS | C6: =AI9 -> 0 | D6: =SUM(P27:$P$61) -> 0 | X6: =SUM(U6:W6) -> 0 | Y6: =IFERROR($AA$12/$X$9,"-") -> - | Z6: =IFERROR(T6+Y6,"-") -> - | AA6: =IFERROR(X6*Z6,"-") -> - | AC6: =$S$6 -> 0 | AD6: =T43 -> 0 | AE6: =U43-U52 -> 0 | AF6: =V43-V52 -> 0 | AG6: =W43-W52 -> 0 | AH6: =SUM(AE6:AG6) -> 0 | AI6: =IFERROR(AD6*AH6,"-") -> 0
B7: Otros ingresos | C7: 0 | X7: =SUM(U7:W7) -> 0 | Y7: =IFERROR($AA$12/$X$9,"-") -> - | Z7: =IFERROR(T7+Y7,"-") -> - | AA7: =IFERROR(X7*Z7,"-") -> - | AE7: =U44-U53 -> 0 | AF7: =V44-V53 -> 0 | AG7: =W44-W53 -> 0 | AH7: =SUM(AE7:AG7) -> 0 | AI7: =IFERROR(AD7*AH7,"-") -> 0
B8: TOTAL INGRESOS | C8: =SUM(C6:C7) -> 0 | D8: =SUM(D6:D7) -> 0 | X8: =SUM(U8:W8) -> 0 | Y8: =IFERROR($AA$12/$X$9,"-") -> - | Z8: =IFERROR(T8+Y8,"-") -> - | AA8: =IFERROR(X8*Z8,"-") -> - | AE8: =U45-U54 -> 0 | AF8: =V45-V54 -> 0 | AG8: =W45-W54 -> 0 | AH8: =SUM(AE8:AG8) -> 0 | AI8: =IFERROR(AD8*AH8,"-") -> 0
B9: Gasto Blanks 1 | C9: =-$Z$28 -> 0 | D9: =C9 -> 0 | S9: TOTAL | X9: =SUM(X3:X8) -> 0 | AA9: =SUM(AA3:AA8) -> 0 | AC9: INGRESOS TOTALES FINALES | AH9: =SUM(AH3:AH8) -> 0 | AI9: =SUM(AI3:AI8) -> 0
B10: Gasto Serigrafia | C10: =-$X$37 -> 0 | D10: =C10 -> 0 | S10: Envio
B11: Otros gastos | S11: Otros gastos
S12: TOTAL EXTRAS | AA12: =SUM(AA10:AA11) -> 0
S13: BLANKS TOTAL | AA13: =AA9 -> 0
B14: TOTAL GASTOS | C14: =SUM(C9:C13) -> 0 | D14: =SUM(D9:D13) -> 0 | AA14: =T3*X3+T4*X4+T5*X5+T6*X6+T7*X7+T8*X8+AA12-AA13 -> 0
S15: BLANKS 2 | T15: UND€ | U15: M | V15: L | W15: XL | X15: UNIDADES | Y15: EXTRA | Z15: € PER UND | AA15: TOTAL
X16: =SUM(U16:W16) -> 0 | Y16: =IFERROR($AA$12/$X$9,"-") -> - | Z16: =IFERROR(T16+Y16,"-") -> - | AA16: =IFERROR(X16*Z16,"-") -> -
B17: BENEFICIO | C17: =C8+C14 -> 0 | D17: =D8+D14 -> 0 | X17: =SUM(U17:W17) -> 0 | Y17: =IFERROR($AA$12/$X$9,"-") -> - | Z17: =IFERROR(T17+Y17,"-") -> - | AA17: =IFERROR(X17*Z17,"-") -> -
X18: =SUM(U18:W18) -> 0 | Y18: =IFERROR($AA$12/$X$9,"-") -> - | Z18: =IFERROR(T18+Y18,"-") -> - | AA18: =IFERROR(X18*Z18,"-") -> -
B19: RATIO DE BLANKS | C19: =IFERROR(ABS($C$9/$C$8),"-") -> - | D19: =IFERROR(ABS($D$10/$D$8),"-") -> - | X19: =SUM(U19:W19) -> 0 | Y19: =IFERROR($AA$12/$X$9,"-") -> - | Z19: =IFERROR(T19+Y19,"-") -> - | AA19: =IFERROR(X19*Z19,"-") -> -
B20: COR% | C20: =IFERROR(ABS($C$14/$C$8),"-") -> - | D20: =IFERROR(ABS($D$14/$D$8),"-") -> - | X20: =SUM(U20:W20) -> 0 | Y20: =IFERROR($AA$12/$X$9,"-") -> - | Z20: =IFERROR(T20+Y20,"-") -> - | AA20: =IFERROR(X20*Z20,"-") -> -
X21: =SUM(U21:W21) -> 0 | Y21: =IFERROR($AA$12/$X$9,"-") -> - | Z21: =IFERROR(T21+Y21,"-") -> - | AA21: =IFERROR(X21*Z21,"-") -> -
C22: =$S$3 -> 0 | F22: =$S$4 -> 0 | I22: =$S$5 -> 0 | L22: =$S$6 -> 0 | S22: TOTAL | X22: =SUM(X16:X21) -> 0 | AA22: =SUM(AA16:AA21) -> 0
C23: M | D23: L | E23: XL | F23: M | G23: L | H23: XL | I23: M | J23: L | K23: XL | L23: M | M23: L | N23: XL | O23: TOTAL | S23: Envio
B24: SOLD | C24: =SUM(C27:C61) -> 0 | D24: =SUM(D27:D61) -> 0 | E24: =SUM(E27:E61) -> 0 | F24: =SUM(F27:F61) -> 0 | G24: =SUM(G27:G61) -> 0 | H24: =SUM(H27:H61) -> 0 | I24: =SUM(I27:I61) -> 0 | J24: =SUM(J27:J61) -> 0 | ... N24: =SUM(N27:N61) -> 0 | O24: =SUM(C24:N24) -> 0 | P24: =O24-SUM(O27:O61) -> 0 | S24: Otros gastos
B25: STOCK | C25: =AE3-C24 -> 0 | D25: =AF3-D24 -> 0 | E25: =AG3-E24 -> 0 | F25: =AE4-F24 -> 0 | G25: =AF4-G24 -> 0 | H25: =AG4-H24 -> 0 | I25: =AE5-I24 -> 0 | J25: =AF5-J24 -> 0 | K25: =AG5-K24 -> 0 | L25: =AE6-L24 -> 0 | M25: =AF6-M24 -> 0 | N25: =AG6-N24 -> 0 | O25: =SUM(C25:N25) -> 0 | S25: TOTAL EXTRAS | AA25: =SUM(AA23:AA24) -> 0
B26: NOMBRE | O26: UNIDADES | P26: INGRESO | Q26: FECHA | S26: BLANKS TOTAL | AA26: =-AA22 -> 0
A27: 1 | O27: =SUM(C27:N27) -> 0 | P27: =IFERROR(((C27+D27+E27)*$AD$3)+((F27+G27+H27)*$AD$4)+((I27+J27+K27)*$AD$5)+((L27+M27+N27)*$AD$6),"-") -> 0 | Z27: =T16*X16+T17*X17+T18*X18+T19*X19+T20*X20+T21*X21+AA25+AA26 -> 0
A28: 2 | O28: =SUM(C28:N28) -> 0 | P28: =IFERROR(((C28+D28+E28)*$AD$3)+((F28+G28+H28)*$AD$4)+((I28+J28+K28)*$AD$5)+((L28+M28+N28)*$AD$6),"-") -> 0 | S28: COSTE TOTAL BLANKS | Z28: =AA13+AA26 -> 0
A29: 3 | O29: =SUM(C29:N29) -> 0 | P29: =IFERROR(((C29+D29+E29)*$AD$3)+((F29+G29+H29)*$AD$4)+((I29+J29+K29)*$AD$5)+((L29+M29+N29)*$AD$6),"-") -> 0
A30: =A29+1 -> 4 | O30: =SUM(C30:N30) -> 0 | P30: =IFERROR(((C30+D30+E30)*$AD$3)+((F30+G30+H30)*$AD$4)+((I30+J30+K30)*$AD$5)+((L30+M30+N30)*$AD$6),"-") -> 0 | S30: SERIGRAFIA | T30: €/UND | U30: UNIDADES | V30: IVA | W30: € PER UND | X30: TOTAL
A31: =A30+1 -> 5 | O31: =SUM(C31:N31) -> 0 | P31: =IFERROR(((C31+D31+E31)*$AD$3)+((F31+G31+H31)*$AD$4)+((I31+J31+K31)*$AD$5)+((L31+M31+N31)*$AD$6),"-") -> 0 | S31: =$S$3 -> 0 | U31: =X3 -> 0 | V31: =IFERROR(((T31*U31)*0.21)/U31,"-") -> - | W31: =IFERROR(T31+V31,"-") -> - | X31: =IFERROR(U31*W31,"-") -> -
A32: =A31+1 -> 6 | O32: =SUM(C32:N32) -> 0 | P32: =IFERROR(((C32+D32+E32)*$AD$3)+((F32+G32+H32)*$AD$4)+((I32+J32+K32)*$AD$5)+((L32+M32+N32)*$AD$6),"-") -> 0 | S32: =$S$4 -> 0 | U32: =X4 -> 0 | V32: =IFERROR(((T32*U32)*0.21)/U32,"-") -> - | W32: =IFERROR(T32+V32,"-") -> - | X32: =IFERROR(U32*W32,"-") -> -
A33: =A32+1 -> 7 | O33: =SUM(C33:N33) -> 0 | P33: =IFERROR(((C33+D33+E33)*$AD$3)+((F33+G33+H33)*$AD$4)+((I33+J33+K33)*$AD$5)+((L33+M33+N33)*$AD$6),"-") -> 0 | S33: =$S$5 -> 0 | U33: =X5 -> 0 | V33: =IFERROR(((T33*U33)*0.21)/U33,"-") -> - | W33: =IFERROR(T33+V33,"-") -> - | X33: =IFERROR(U33*W33,"-") -> -
A34: =A33+1 -> 8 | O34: =SUM(C34:N34) -> 0 | P34: =IFERROR(((C34+D34+E34)*$AD$3)+((F34+G34+H34)*$AD$4)+((I34+J34+K34)*$AD$5)+((L34+M34+N34)*$AD$6),"-") -> 0 | S34: =$S$6 -> 0 | U34: =X6 -> 0 | V34: =IFERROR(((T34*U34)*0.21)/U34,"-") -> - | W34: =IFERROR(T34+V34,"-") -> - | X34: =IFERROR(U34*W34,"-") -> -
A35: =A34+1 -> 9 | O35: =SUM(C35:N35) -> 0 | P35: =IFERROR(((C35+D35+E35)*$AD$3)+((F35+G35+H35)*$AD$4)+((I35+J35+K35)*$AD$5)+((L35+M35+N35)*$AD$6),"-") -> 0 | V35: =IFERROR(((T35*U35)*0.21)/U35,"-") -> - | W35: =IFERROR(T35+V35,"-") -> - | X35: =IFERROR(U35*W35,"-") -> -
A36: =A35+1 -> 10 | O36: =SUM(C36:N36) -> 0 | P36: =IFERROR(((C36+D36+E36)*$AD$3)+((F36+G36+H36)*$AD$4)+((I36+J36+K36)*$AD$5)+((L36+M36+N36)*$AD$6),"-") -> 0 | V36: =IFERROR(((T36*U36)*0.21)/U36,"-") -> - | W36: =IFERROR(T36+V36,"-") -> - | X36: =IFERROR(U36*W36,"-") -> -
A37: =A36+1 -> 11 | O37: =SUM(C37:N37) -> 0 | P37: =IFERROR(((C37+D37+E37)*$AD$3)+((F37+G37+H37)*$AD$4)+((I37+J37+K37)*$AD$5)+((L37+M37+N37)*$AD$6),"-") -> 0 | S37: SERIGRAFIA TOTAL | U37: =SUM(U31:U36) -> 0 | X37: =SUM(X31:X36) -> 0
A38: =A37+1 -> 12 | O38: =SUM(C38:N38) -> 0 | P38: =IFERROR(((C38+D38+E38)*$AD$3)+((F38+G38+H38)*$AD$4)+((I38+J38+K38)*$AD$5)+((L38+M38+N38)*$AD$6),"-") -> 0
A39: =A38+1 -> 13 | O39: =SUM(C39:N39) -> 0 | P39: =IFERROR(((C39+D39+E39)*$AD$3)+((F39+G39+H39)*$AD$4)+((I39+J39+K39)*$AD$5)+((L39+M39+N39)*$AD$6),"-") -> 0 | S39: INGRESOS | T39: PRECIO | U39: M | V39: L | W39: XL | X39: UNIDADES | Y39: TOTAL
A40: =A39+1 -> 14 | O40: =SUM(C40:N40) -> 0 | P40: =IFERROR(((C40+D40+E40)*$AD$3)+((F40+G40+H40)*$AD$4)+((I40+J40+K40)*$AD$5)+((L40+M40+N40)*$AD$6),"-") -> 0 | S40: =$S$3 -> 0 | T40: =T66 -> 0 | U40: =U3 -> 0 | V40: =V3 -> 0 | W40: =W3 -> 0 | X40: =SUM(U40:W40) -> 0 | Y40: =IFERROR(T40*X40,"-") -> 0
A41: =A40+1 -> 15 | O41: =SUM(C41:N41) -> 0 | P41: =IFERROR(((C41+D41+E41)*$AD$3)+((F41+G41+H41)*$AD$4)+((I41+J41+K41)*$AD$5)+((L41+M41+N41)*$AD$6),"-") -> 0 | S41: =$S$4 -> 0 | T41: =T67 -> 0 | U41: =U4 -> 0 | V41: =V4 -> 0 | W41: =W4 -> 0 | X41: =SUM(U41:W41) -> 0 | Y41: =IFERROR(T41*X41,"-") -> 0
...

Sheet REVOLUT
H2: A33 | J2: DROP 1 | N2: DROP 2 | R2: SUMMER DROP | V2: A33 X NO ART | Z2: DROP 3 | AD2: DROP 4 | AH2: DROP 5
G3: DROP 1 | H3: =L14 -> 1039.41
A4: TOPUP | B4: Current | C4: 44338.993 | D4: A33: 1 SUDAPA GRIS D1 (PETER) | E4: 55 | G4: DROP 2 | H4: =P34 -> 297.92 | J4: 44338.993 | K4: A33: 1 SUDAPA GRIS D1 (PETER) | L4: 55 | N4: =C12 -> 44467.677 | O4: COMPRA RUE PORTER | P4: =E12 -> -780.23 | R4: 44690.781 | S4: COMPRA WORDANS PRUEBA | T4: =E45 -> -9.84 | V4: =C64 -> 44819.083 | W4: COMPRA RUE PORTER | X4: =E64 -> -405.11 | Z4: =C37 -> 44620.86 | AA4: COMPRA RUE PORTER | AB4: =E37 -> -433.02 | AD4: =C77 -> 44872.176 | AE4: COMPRA PRUEBA STUDIOS TC | AF4: =E77 -> -89.68 | AH4: =C114 -> 45260 | AI4: =D114 -> COMPRA STUDIOS TC | AJ4: =E114 -> -713.58
A5: TOPUP | B5: Current | C5: 44341.712 | D5: A33: 1 CAMI MADRID D1 (LUISAN) | E5: 30 | G5: SUMMER DROP | H5: =T20 -> 282.83 | J5: 44341.712 | K5: A33: 1 CAMI MADRID D1 (LUISAN) | L5: 30 | N5: =C13 -> 44467.683 | O5: COMPRA RUE PORTER | P5: =E13 -> -107.2 | R5: 44699.84 | S5: COMPRA WORDANS | T5: =E46 -> -108.16 | V5: =C65 -> 44842.782 | W5: TASAS RUE PORTER | X5: =E65 -> -173.3 | Z5: =C40 -> 44630.828 | AA5: COMPRA MOOJI MOOJI | AB5: =E40 -> -423.53 | AD5: =C80 -> 44887.169 | AE5: DEVOLUCION A STUDIOS TC | AF5: =E80 -> -17.64 | AH5: =C116 -> 45323 | AI5: =D116 -> SERIGRAFIA | AJ5: =E116 -> -228.69
A6: TOPUP | B6: Current | C6: 44392.816 | D6: A33: 1 SUDAPA Y 1 CAMI (JAIME BUST) | E6: 80 | G6: A33 X NO ART | H6: =X20 -> 39.22 | J6: 44392.816 | K6: A33: 1 SUDAPA Y 1 CAMI (JAIME BUST) | L6: 80 | N6: =C14 -> 44471.086 | O6: COMPRA DORTEX | P6: =E14 -> -49.01 | R6: 44706.836 | S6: SERIGRAFIA | T6: =E47 -> -93.17 | V6: =C70 -> 44868.085 | W6: A33: 1 BALACLAVA L Y SKULL L (PETER) | X6: =E70 -> 70 | Z6: =C41 -> 44658.211 | AA6: TASAS MOOJI MOOJI (PAGADO POR MAMA) | AB6: =E41 -> -109.14 | AD6: =C82 -> 44898.375 | AE6: REEMBOLSO DE STUDIOS TC | AF6: =E82 -> 89.68 | AH6: 45372 | AI6: =D119 -> A33: GRAF L Y BRAILE L (DOMINGUEZ) | AJ6: =E119 -> 66
A7: TOPUP | B7: Current | C7: 44399.158 | D7: A33: CAMI VERDE Y BLANCA Y SUDAPA (JAIME$) Y SUDAPA (LUISAN) | E7: 170 | G7: DROP 3 | H7: =AB29 -> -315.56 | J7: 44399.158 | K7: A33: CAMI VERDE Y BLANCA Y SUDAPA (JAIME$) Y SUDAPA (LUISAN) | L7: 170 | N7: =C16 -> 44477.03 | O7: AÑADE DINERO PARA SERIGRAFIA | P7: =E16 -> 178.87 | R7: 44718.755 | S7: A33: 3 SAND XL (JUANMA, MUÑOZ Y PETER) 1 RUSA XL (PETER) | T7: =E49 -> 38 | V7: =C71 -> 44868.092 | W7: A33: 1 BALACLAVA L (JP) | X7: =E71 -> 35.34 | Z7: =C44 -> 44688.992 | AA7: DEVOLUCION RUE PORTER | AB7: =E44 -> 455.17 | AD7: =C90 -> 45034.161 | AE7: COMPRA WEEKDAY | AF7: =E90 -> -108 | AJ7: =I90 -> 0
A8: TOPUP | B8: Current | C8: 44400.061 | D8: A33: SUDAPA (QUINTANA) | E8: 55 | G8: DROP 4 | H8: =AF33 -> -170.55 | J8: 44400.061 | K8: A33: SUDAPA (QUINTANA) | L8: 55 | N8: =C17 -> 44477.036 | O8: SERIGRAFIA | P8: =E17 -> -246.24 | R8: 44718.99 | S8: A33: 1 RUSA XL (PETER) | T8: =E50 -> 38 | V8: =C72 -> 44868.735 | W8: A33: 2 BALACLAVA M (PUPI, LUIS CAN) SKULL XL (SESE) | X8: =E72 -> 105 | Z8: =C66 -> 44848.097 | AA8: SERIGRAFIA | AB8: =E66 -> -29.04 | AD8: =C91 -> 45034.738 | AE8: A33: CREW N L (CASAPE), CAMI XL (JAIME RAMIEZ) | AF8: =E91 -> 78 | AJ8: =I91 -> 0
A9: TOPUP | B9: Current | C9: 44403.834 | D9: A33: SUDAPA GRIS (GENO) | E9: 40.41 | H9: =SUM(H3:H8) -> 1173.27 | J9: 44403.834 | K9: A33: SUDAPA GRIS (GENO) | L9: 40.41 | N9: =C18 -> 44502.812 | O9: APPLE PAY | P9: =E18 -> 40 | R9: 44726.266 | S9: A33: 1 SAND L y 1 RUSA L (Nico) | T9: =E52 -> 38 | V9: =C73 -> 44870.278 | W9: A33: 2 BALACLAVA L (Muñoz) | X9: =E73 -> 35 | Z9: =C67 -> 44848.89 | AA9: COMPRA CAMISETAS FUTBOL | AB9: =E67 -> -387 | AD9: =C92 -> 45035.637 | AE9: COMPRA VELOUR GARMETS | AF9: =E92 -> -634.99 | AJ9: =I92 -> 0
A10: TOPUP | B10: Current | C10: 44410.081 | D10: A33: 3 SUDAPAS 1 CAMI BLANCA (MUÑOZ) Y SUDAPA GRIS (AMIGA GENO) | E10: 272 | J10: 44410.081 | K10: A33: 3 SUDAPAS 1 CAMI BLANCA (MUÑOZ) Y SUDAPA GRIS (AMIGA GENO) | L10: 272 | N10: =C19 -> 44503.724 | O10: COMPRA PEGATINAS | P10: =E19 -> -26.33 | R10: 44728.932 | S10: A33: 1 RUSA XL (ASTARLOA) | T10: =E53 -> 19 | V10: =C74 -> 44871.174 | W10: A33: 1 BALACLAVA M (Dominguez), 2 SKULL ML (N.Per y N.Ben) | X10: =E74 -> 105 | Z10: =C68 -> 44863.065 | AA10: A33: MOOJI L (CARMEN) | AB10: =E68 -> 69 | AD10: =C93 -> 45035.702 | AE10: COMPRA STUDIOS TC | AF10: =E93 -> -357.25 | AJ10: =I93 -> 0
A11: TOPUP | B11: Current | C11: 44454.166 | D11: A33: 1 SUDAPA, 3 CAMIS BLANCAS, 3 CAMIS VERDES (AMIGOS JACO) | E11: 255 | J11: 44454.166 | K11: A33: 1 SUDAPA, 3 CAMIS BLANCAS, 3 CAMIS VERDES (AMIGOS JACO) | L11: 255 | N11: =C20 -> 44514.179 | O11: A33: CAMI TIRO L Y CAMI PIVA L (DOMINGEZ) | P11: =E20 -> 63 | R11: 44729.223 | S11: A33: 1 MANOS XL (RUBINI) | T11: =E54 -> 19 | V11: =C75 -> 44871.175 | W11: A33: 1 BALACLAVA L (C.Chorvo), 2 SKULL ML (C.chorv y cuervo) | X11: =E75 -> 105 | Z11: =C69 -> 44868.085 | AA11: A33: FUTBOL XL (PETER) | AB11: =E69 -> 36 | AD11: =C96 -> 45043.269 | AE11: A33: CREW N M, CAMI L (PETER) | AF11: =E96 -> 78 | AJ11: =I96 -> 0
A12: CARD_PAYMENT | B12: Current | C12: 44467.677 | D12: COMPRA RUE PORTER | E12: -780.23 | J12: 44472.893 | K12: A33: 1 SUDAPA TIRO D1 (PETER) | L12: 50 | N12: =C21 -> 44515.68 | O12: A33: CAMI TIRO M (PETER) | P12: =E21 -> 34.37 | R12: 44730.408 | S12: A33: 3 RUSAS L Y 1 XL (PUIG,JUANTO,BRABUS,DOMING), 1 MANOS L (JUANTO) | T12: =E55 -> 95 | V12: =C76 -> 44871.284 | W12: SERIGRAFIA | X12: =E76 -> -212.71 | Z12: =C84 -> 44938.718 | AA12: A33: REVOLUTION L (IÑIGO) | AB12: =E84 -> 69 | AD12: =C97 -> 45043.27 | AE12: A33: CREW M L (LAURA), CREW N M (IAGO) | AF12: =E97 -> 88 | AJ12: =I97 -> 0
A13: CARD_PAYMENT | B13: Current | C13: 44467.683 | D13: COMPRA RUE PORTER | E13: -107.2 | J13: 44626.071 | K13: A33: 1 SUDAPA CARA D1 (AMIGO JAIME) | L13: 32 | N13: =C22 -> 44516.098 | O13: A33: EFECTIVO Y OTRO | P13: =E22 -> 187 | R13: 44730.87 | S13: A33: 1 MANOS L (CHORBO) | T13: =E56 -> 19 | V13: =C78 -> 44875.727 | W13: A33: 1 BALACLAVA M (Nistal), 2 SKULL ML (Juanto, Barallobre) | X13: =E78 -> 105 | Z13: =C86 -> 44982.198 | AA13: A33: FUTBOL XL (ALEX DELCLAUX) | AB13: =E86 -> 33 | AD13: =C98 -> 45043.659 | AE13: SERIGRAFIA | AF13: =E98 -> -217.8 | AJ13: =I98 -> 0
A14: CARD_PAYMENT | B14: Current | C14: 44471.086 | D14: COMPRA DORTEX | E14: -49.01 | L14: =SUM(L4:L13) -> 1039.41 | N14: =C23 -> 44516.168 | O14: A33: OTRO | P14: =E23 -> 63 | R14: 44734.16 | S14: A33: 1 RUSA L (DIRECTOR) | T14: =E57 -> 19 | V14: =C79 -> 44876.766 | W14: A33: 1 BALACLAVA M (GABRIEL) | X14: =E79 -> 35 | Z14: =C87 -> 44994.152 | AA14: A33: FUTBOL XL (IAGO) REVOLUTION L (TITO) | AB14: =E87 -> 96 | AD14: =C100 -> 45066.87 | AE14: A33: 2 CREW N M (nico y juli), CAMI ML (Nico y weister) | AF14: =E100 -> 154 | AJ14: =I100 -> 0
A15: TOPUP | B15: Current | C15: 44472.893 | D15: A33: 1 SUDAPA TIRO D1 (PETER) | E15: 50 | N15: =C24 -> 44517.234 | O15: A33: SUDAPA M, CAMI MARRON M (PUIG) | P15: =E24 -> 78 | R15: 44734.714 | S15: A33: 1 RUSA L (NACHO), RUSA XL MANOS XL (JOSE) | T15: =E58 -> 57 | V15: =C81 -> 44887.212 | W15: A33: 1 BALACLAVA M (nathan) | X15: =E81 -> 35 | Z15: =C88 -> 44994.157 | AA15: A33: REVOLUTION M (BRUNO) | AB15: =E88 -> 63 | AD15: =C101 -> 45067.205 | AE15: A33: 4 CAMI 3L 1M (FELIX, TITO, CASADO Y FORMAS) | AF15: =E101 -> 136 | AJ15: =I101 -> 0
A16: TOPUP | B16: Current | C16: 44477.03 | D16: AÑADE DINERO PARA SERIGRAFIA | E16: 178.87 | N16: =C25 -> 44527.932 | O16: A33: OTRO | P16: =E25 -> 78 | R16: 44736.823 | S16: A33: 1 RUSA L Y XL (CASADO Y BARALLOBRE), MANOS L Y XL (IAGO Y BARALLOBRE) | T16: =E59 -> 76 | V16: =C83 -> 44899.092 | W16: A33: 2 BALACLAVA M y L (Zorrila y Dani cris arte) | X16: =E83 -> 70 | Z16: =C95 -> 45043.264 | AA16: A33: 2 REVOLUTION M Y L (JORDI Y PETER) | AB16: =E95 -> 123 | AD16: =C102 -> 45067.212 | AE16: A33: 2 CAMI L(PUPI y rubini) y SUDAPA M L (RUBAS) | AF16: =E102 -> 112 | AJ16: =I102 -> 0
A17: TRANSFER | B17: Current | C17: 44477.036 | D17: SERIGRAFIA | E17: -246.24 | N17: =C26 -> 44536.097 | O17: A33: SUDAPA M (FORMARIZ) | P17: =E26 -> 49 | R17: 44743.054 | S17: A33: 1 MANOS L (JORDI) | T17: =E60 -> 19 | V17: =C85 -> 44938.72 | W17: A33: 1 BALACLAVA L (JAIME), SKULL M (JAIME) | X17: =E85 -> 70 | Z17: =C99 -> 45063.18 | AA17: A33: 1 FUTBOL L (SAMUEL) | AB17: =E99 -> 30 | AD17: =C103 -> 45079.027 | AE17: A33: 2 CAMI L(MONICA Y CAMA) y SUDAPA M M (ANNA) | AF17: =E103 -> 112.01 | AJ17: =I103 -> 0
A18: TOPUP | B18: Current | C18: 44502.812 | D18: APPLE PAY | E18: 40 | N18: =C27 -> 44537.173 | O18: A33: SUDAPA L (STRIPE) | P18: =E27 -> 52.7 | R18: 44783.086 | S18: A33: 1 MANOS XL Y RUSA XL (IÑIGO) | T18: =E61 -> 38 | V18: =C89 -> 44994.157 | W18: A33: 1 BALACLAVA M (BRUNO) | X18: =E89 -> 35 | Z18: =C106 -> 45101.156 | AA18: A33: 1 FUTBOL L (VICTOR) | AB18: =E106 -> 33 | AD18: =C104 -> 45091.817 | AE18: A33: 2 CAMI XL(MUÑOZ) y SUDAPA N M (CHIARRI) | AF18: =E104 -> 78.12 | AJ18: =I104 -> 0
A19: CARD_PAYMENT | B19: Current | C19: 44503.724 | D19: COMPRA PEGATINAS | E19: -26.33 | N19: =C28 -> 44540.681 | O19: A33: CAMI MARRON L (MUÑOZ) | P19: =E28 -> 29 | R19: 44783.285 | S19: A33: 1 MANOS L (BRUNO) | T19: =E62 -> 19 | V19: =C94 -> 45041.09 | W19: A33: 1 BALACLAVA L (BARALLOBRE) | X19: =E94 -> 25 | Z19: =C109 -> 45105.731 | AA19: A33: 1 FUTBOL L (VINTED) | AB19: =E109 -> 33 | AD19: =C105 -> 45098.102 | AE19: A33: CAMI L (QUINTANA) | AF19: =E105 -> 34 | AJ19: =I105 -> 0
A20: TOPUP | B20: Current | C20: 44514.179 | D20: A33: CAMI TIRO L Y CAMI PIVA L (DOMINGEZ) | E20: 63 | N20: =C29 -> 44545.051 | O20: A33: SUDAPA L (STRIPE) | P20: =E29 -> 54.3 | T20: =SUM(T4:T19) -> 282.83 | X20: =SUM(X4:X19) -> 39.22 | Z20: 45251 | AA20: A33: FUTBOL XL (VINTED) | AB20: =E113 -> 26 | AD20: =C107 -> 45101.156 | AE20: A33: SUDAPA N M (luisan) | AF20: =E107 -> 44 | AJ20: =I107 -> 0
A21: TOPUP | B21: Current | C21: 44515.68 | D21: A33: CAMI TIRO M (PETER) | E21: 34.37 | N21: =C30 -> 44548.915 | O21: A33: CAMI TIRO L (RODRI) | P21: =E30 -> 34 | AB21: 0 | AD21: =C108 -> 45105.731 | AE21: A33: CAMI L (JUANMA) | AF21: =E108 -> 30 | AJ21: =I108 -> 0
A22: TOPUP | B22: Current | C22: 44516.098 | D22: A33: EFECTIVO Y OTRO | E22: 187 | N22: =C31 -> 44549.115 | O22: A33: 1 SUDAPA OJOS L (TITO) | P22: =E31 -> 45 | AB22: 0 | AD22: =C110 -> 45133.818 | AE22: A33: CAMI M y XL (NACHO.P Y MARQUINA) | AF22: =E110 -> 66 | AJ22: =I110 -> 0
A23: TOPUP | B23: Current | C23: 44516.168 | D23: A33: OTRO | E23: 63 | N23: =C32 -> 44550.201 | O23: A33: SUDAPA L (ALVARO NISTAL) | P23: =E32 -> 39 | AB23: 0 | AD23: =C111 -> 45240.911 | AE23: A33: CAMI M y sudapa M (CHORVO) | AF23: =E111 -> 78 | AJ23: =I111 -> 0
A24: TOPUP | B24: Current | C24: 44517.234 | D24: A33: SUDAPA M, CAMI MARRON M (PUIG) | E24: 78 | N24: =C33 -> 44551.387 | O24: A33: SUDAPA L (MARIO MIRON) | P24: =E33 -> 49 | AB24: 0 | AD24: =C112 -> 45244.929 | AE24: A33: CAMI L (BARALLOBRE) | AF24: =E112 -> 33 | AJ24: =I112 -> 0
A25: TOPUP | B25: Current | C25: 44527.932 | D25: A33: OTRO | E25: 78 | N25: =C34 -> 44557.358 | O25: A33: SUDAPA M (CHIARRI) | P25: =E34 -> 39 | AB25: 0 | AD25: 45260 | AE25: A33: SUDAPA L M (RITXI) | AF25: =E115 -> 44 | AJ25: =I115 -> 0
A26: TOPUP | B26: Current | C26: 44536.097 | D26: A33: SUDAPA M (FORMARIZ) | E26: 49 | N26: =C35 -> 44561.25 | O26: A33: SUDAPA M (AMIGO MUÑOZ) | P26: =E35 -> 49 | AB26: 0 | AF26: 0 | AJ26: 0
A27: TOPUP | B27: Current | C27: 44537.173 | D27: A33: SUDAPA L (STRIPE) | E27: 52.7 | N27: =C36 -> 44620.858 | O27: A33: VINTED | P27: =E36 -> 73 | AB27: 0 | AF27: 0 | AJ27: 0
A28: TOPUP | B28: Current | C28: 44540.681 | D28: A33: CAMI MARRON L (MUÑOZ) | E28: 29 | N28: =C39 -> 44626.071 | O28: A33: 2 CAMI TIRO M Y L, 2 CAMI PIVA M (JAIME Y AMIGO) | P28: =E39 -> 100.02 | AB28: 0 | AF28: 0 | AJ28: 0
A29: TOPUP | B29: Current | C29: 44545.051 | D29: A33: SUDAPA L (STRIPE) | E29: 54.3 | N29: =C42 -> 44658.724 | O29: A33: SUDAPA OJOS L (IÑIGO) | P29: =E42 -> 40.67 | AB29: =SUM(AB4:AB28) -> -315.56 | AF29: 0 | AJ29: 0
A30: TOPUP | B30: Current | C30: 44548.915 | D30: A33: CAMI TIRO L (RODRI) | E30: 34 | N30: =C43 -> 44677.237 | O30: A33: CAMI TIRO M (NICO) | P30: =E43 -> 25 | AF30: 0 | AJ30: 0
A31: TOPUP | B31: Current | C31: 44549.115 | D31: A33: 1 SUDAPA OJOS L (TITO) | E31: 45 | N31: =C48 -> 44716.206 | O31: A33: CAMI TIRO M (BARTA) | P31: =E48 -> 25 | AF31: 0 | AJ31: 0
A32: TOPUP | B32: Current | C32: 44550.201 | D32: A33: SUDAPA L (ALVARO NISTAL) | E32: 39 | N32: =C51 -> 44722.86 | O32: A33: CAMI TIRO L (QUINTANA) | P32: =E51 -> 25 | AF32: 0 | AJ32: 0
A33: TOPUP | B33: Current | C33: 44551.387 | D33: A33: SUDAPA L (MARIO MIRON) | E33: 49 | N33: =C63 -> 44783.285 | O33: A33: CAMI MARRON L , CAMI TIRO M (CASAPE, SANZ = DEUDA JACO) | P33: =E63 -> 56 | AF33: =SUM(AF4:AF32) -> -170.55 | AJ33: =SUM(AJ4:AJ32) -> -876.27
A34: TOPUP | B34: Current | C34: 44557.358 | D34: A33: SUDAPA M (CHIARRI) | E34: 39 | P34: =SUM(P4:P33) -> 297.92
A35: TOPUP | B35: Current | C35: 44561.25 | D35: A33: SUDAPA M (AMIGO MUÑOZ) | E35: 49
A36: TOPUP | B36: Current | C36: 44620.858 | D36: A33: VINTED | E36: 73
A37: CARD_PAYMENT | B37: Current | C37: 44620.86 | D37: COMPRA RUE PORTER | E37: -433.02
A38: TOPUP | B38: Current | C38: 44626.071 | D38: A33: 1 SUDAPA CARA D1 (AMIGO JAIME) | E38: 32
A39: TOPUP | B39: Current | C39: 44626.071 | D39: A33: 2 CAMI TIRO M Y L, 2 CAMI PIVA M (JAIME Y AMIGO) | E39: 100.02
A40: CARD_PAYMENT | B40: Current | C40: 44630.828 | D40: COMPRA MOOJI MOOJI | E40: -423.53
A41: TRANSFER | B41: Current | C41: 44658.211 | D41: TASAS MOOJI MOOJI (PAGADO POR MAMA) | E41: -109.14
...

Sheet DROP 1
B2: DROP 1 | P2: INGRESOS FINALES | Q2: PRECIO | R2: M | S2: L | T2: UNIDADES | U2: TOTAL | Y2: INGRESOS | Z2: PRECIO | AA2: M | AB2: L | AC2: UNIDADES | AD2: TOTAL
P3: =$P$27 -> MIRILLA | Q3: =Z3 -> 55 | R3: =AA3-AA12 -> 7 | S3: =AB3-AB12 -> 2 | T3: =SUM(R3:S3) -> 9 | U3: =IFERROR(Q3*T3,"-") -> 495 | Y3: =$P$27 -> MIRILLA | Z3: =Z35 -> 55 | AA3: =R27 -> 8 | AB3: =S27 -> 2 | AC3: =SUM(AA3:AB3) -> 10 | AD3: =IFERROR(Z3*AC3,"-") -> 550
P4: =$P$28 -> CARA | Q4: =Z4 -> 55 | R4: =AA4-AA13 -> 5 | S4: =AB4-AB13 -> 0 | T4: =SUM(R4:S4) -> 5 | U4: =IFERROR(Q4*T4,"-") -> 275 | Y4: =$P$28 -> CARA | Z4: =Z36 -> 55 | AA4: =R28 -> 6 | AB4: =S28 -> 0 | AC4: =SUM(AA4:AB4) -> 6 | AD4: =IFERROR(Z4*AC4,"-") -> 330
C5: PPTO | D5: REAL | P5: =$P$29 -> AIRLINE | Q5: =Z5 -> 30 | R5: =AA5-AA14 -> 6 | S5: =AB5-AB14 -> 0 | T5: =SUM(R5:S5) -> 6 | U5: =IFERROR(Q5*T5,"-") -> 180 | Y5: =$P$29 -> AIRLINE | Z5: =Z37 -> 30 | AA5: =R29 -> 8 | AB5: =S29 -> 0 | AC5: =SUM(AA5:AB5) -> 8 | AD5: =IFERROR(Z5*AC5,"-") -> 240
B6: INGRESOS | C6: =U9 -> 1130 | D6: =SUM(L27:$L$61) -> 1049 | P6: =$P$30 -> MADRID | Q6: =Z6 -> 30 | R6: =AA6-AA15 -> 6 | S6: =AB6-AB15 -> 0 | T6: =SUM(R6:S6) -> 6 | U6: =IFERROR(Q6*T6,"-") -> 180 | Y6: =$P$30 -> MADRID | Z6: =Z38 -> 30 | AA6: =R30 -> 8 | AB6: =S30 -> 0 | AC6: =SUM(AA6:AB6) -> 8 | AD6: =IFERROR(Z6*AC6,"-") -> 240
B7: Otros ingresos | C7: 0 | R7: =AA7-AA16 -> 0 | S7: =AB7-AB16 -> 0 | T7: =SUM(R7:S7) -> 0 | U7: =IFERROR(Q7*T7,"-") -> 0 | AA7: =R31 -> 0 | AB7: =S31 -> 0 | AC7: =SUM(AA7:AB7) -> 0 | AD7: =IFERROR(Z7*AC7,"-") -> 0
B8: TOTAL INGRESOS | C8: =SUM(C6:C7) -> 1130 | D8: =SUM(D6:D7) -> 1049 | R8: =AA8-AA17 -> 0 | S8: =AB8-AB17 -> 0 | T8: =SUM(R8:S8) -> 0 | U8: =IFERROR(Q8*T8,"-") -> 0 | AA8: =R32 -> 0 | AB8: =S32 -> 0 | AC8: =SUM(AA8:AB8) -> 0 | AD8: =IFERROR(Z8*AC8,"-") -> 0
B9: Gasto Blanks 1 | C9: =$W$52 -> -655.48 | D9: =C9 -> -655.48 | P9: INGRESOS TOTALES FINALES | T9: =SUM(T3:T8) -> 26 | U9: =SUM(U3:U8) -> 1130 | Y9: INGRESOS TOTALES | AC9: =SUM(AC3:AC8) -> 32 | AD9: =SUM(AD3:AD8) -> 1360
B10: Gasto Serigrafia | C10: =$U$61 -> -116.16 | D10: =C10 -> -116.16
B11: Etiquetas | C11: =-66.46 -> -66.46 | D11: =C11 -> -66.46 | Y11: GON JACO | Z11: COSTE | AA11: M | AB11: L | AC11: UNIDADES | AD11: TOTAL
B12: Otros gastos | Y12: =$P$27 -> MIRILLA | Z12: =AA35 -> -34.7825 | AA12: 1 | AC12: =SUM(AA12:AB12) -> 1 | AD12: =IFERROR(Z12*AC12,"-") -> -34.7825
Y13: =$P$28 -> CARA | Z13: =AA36 -> -33.0825 | AA13: 1 | AC13: =SUM(AA13:AB13) -> 1 | AD13: =IFERROR(Z13*AC13,"-") -> -33.0825
B14: TOTAL GASTOS | C14: =SUM(C9:C13) -> -838.1 | D14: =SUM(D9:D13) -> -838.1 | Y14: =$P$29 -> AIRLINE | Z14: =AA37 -> -14.0825 | AA14: 2 | AC14: =SUM(AA14:AB14) -> 2 | AD14: =IFERROR(Z14*AC14,"-") -> -28.165
Y15: =$P$30 -> MADRID | Z15: =AA38 -> -14.0825 | AA15: 2 | AC15: =SUM(AA15:AB15) -> 2 | AD15: =IFERROR(Z15*AC15,"-") -> -28.165
AC16: =SUM(AA16:AB16) -> 0 | AD16: =IFERROR(Z16*AC16,"-") -> 0
B17: BENEFICIO | C17: =C8+C14 -> 291.9 | D17: =D8+D14 -> 210.9 | AC17: =SUM(AA17:AB17) -> 0 | AD17: =IFERROR(Z17*AC17,"-") -> 0
Y18: COSTE TOTAL | AC18: =SUM(AC12:AC17) -> 6 | AD18: =SUM(AD12:AD17) -> -124.195
B19: RATIO DE BLANKS | C19: =IFERROR(ABS($C$9/$C$8),"-") -> 0.5800708 | D19: =IFERROR(ABS($D$10/$D$8),"-") -> 0.11073403
B20: COR% | C20: =IFERROR(ABS($C$14/$C$8),"-") -> 0.74168142 | D20: =IFERROR(ABS($D$14/$D$8),"-") -> 0.79895138
C22: =$P$27 -> MIRILLA | E22: =$P$28 -> CARA | G22: =$P$29 -> AIRLINE | I22: =$P$30 -> MADRID
C23: M | D23: L | E23: M | F23: L | G23: M | H23: L | I23: M | J23: L | K23: TOTAL
B24: SOLD | C24: =SUM(C27:C61) -> 7 | D24: =SUM(D27:D61) -> 2 | E24: =SUM(E27:E61) -> 4 | F24: =SUM(F27:F61) -> 0 | G24: =SUM(G27:G61) -> 6 | H24: =SUM(H27:H61) -> 0 | I24: =SUM(I27:I61) -> 6 | J24: =SUM(J27:J61) -> 0 | K24: =SUM(C24:J24) -> 25 | L24: =K24-SUM(K27:K61) -> 0
B25: STOCK | C25: =R3-C24 -> 0 | D25: =S3-D24 -> 0 | E25: =R4-E24 -> 1 | F25: =S4-F24 -> 0 | G25: =R5-G24 -> 0 | H25: =S5-H24 -> 0 | I25: =R6-I24 -> 0 | J25: =S6-J24 -> 0 | K25: =SUM(C25:J25) -> 1
B26: NOMBRE | K26: UNIDADES | L26: INGRESO | M26: FECHA | P26: BLANKS 1 | Q26: UND€ | R26: M | S26: L | T26: UNIDADES | U26: EXTRA | V26: € PER UND | W26: TOTAL | Y26: COSTE POR UND | Z26: BLANKS | AA26: SERIGRAFIA | AB26: EXTRA | AC26: TOTAL
